File: 40 per.is_metal_RawData/Specimen_RawData_1.csv
Time,Extension,Load,Tensile stress,Tensile strain (Extension)
(s),(mm),(N),(MPa),(mm/mm)
"0.00000","0.00000","-0.77403","-0.07011","0.00000"
"0.28800","0.00200","21.08837","1.91018","0.00008"
"0.57600","0.00494","58.92195","5.33713","0.00019"
"0.86400","0.00725","88.79726","8.04323","0.00029"
"1.15200","0.01000","121.42747","10.99887","0.00039"
"1.44000","0.01219","147.75478","13.38358","0.00048"
"1.72800","0.01437","173.15146","15.68401","0.00057"
"2.01600","0.01700","203.61194","18.44311","0.00067"
"2.30400","0.01925","228.61246","20.70765","0.00076"
"2.59200","0.02200","258.03180","23.37245","0.00087"
"2.88000","0.02419","280.31937","25.39125","0.00095"
"3.16800","0.02637","302.04431","27.35909","0.00104"
"3.45600","0.02900","328.42010","29.74820","0.00114"
"3.74400","0.03125","350.49066","31.74734","0.00123"
"4.03200","0.03394","376.75162","34.12605","0.00134"
"4.32000","0.03631","397.20135","35.97838","0.00143"
"4.60800","0.03837","415.41812","37.62845","0.00151"
"4.89600","0.04100","439.04678","39.76873","0.00161"
"5.18400","0.04319","457.48163","41.43855","0.00170"
"5.47200","0.04594","481.63809","43.62664","0.00181"
"5.76000","0.04825","498.23965","45.13041","0.00190"
"6.04800","0.05037","514.20813","46.57682","0.00198"
"6.33600","0.05306","535.40167","48.49653","0.00209"
"6.62400","0.05519","550.11945","49.82966","0.00217"
"6.91200","0.05794","571.36713","51.75427","0.00228"
"7.20000","0.06025","585.80280","53.06185","0.00237"
"7.48800","0.06250","599.70966","54.32153","0.00246"
"7.77600","0.06500","616.14502","55.81024","0.00256"
"8.06400","0.06719","628.41394","56.92155","0.00265"
"8.35200","0.06994","646.64587","58.57299","0.00275"
"8.64000","0.07225","659.21051","59.71110","0.00284"
"8.92800","0.07444","669.66919","60.65844","0.00293"
"9.21600","0.07706","683.30536","61.89360","0.00303"
"9.50400","0.07919","692.80066","62.75368","0.00312"
"9.79200","0.08187","707.44171","64.07986","0.00322"
"10.08000","0.08425","717.60577","65.00053","0.00332"
"10.36800","0.08650","726.74280","65.82816","0.00341"
"10.65600","0.08912","738.16187","66.86249","0.00351"
"10.94400","0.09112","744.39038","67.42667","0.00359"
"11.23200","0.09387","756.88470","68.55840","0.00370"
"11.52000","0.09625","765.27228","69.31814","0.00379"
"11.80800","0.09856","772.99506","70.01767","0.00388"
"12.09600","0.10106","781.28510","70.76858","0.00398"
"12.38400","0.10312","785.82019","71.17937","0.00406"
"12.67200","0.10587","795.78925","72.08236","0.00417"
"12.96000","0.10825","802.42303","72.68324","0.00426"
"13.24800","0.11056","808.53540","73.23690","0.00435"
"13.53600","0.11306","815.63385","73.87988","0.00445"
"13.82400","0.11519","818.75629","74.16270","0.00453"
"14.11200","0.11781","826.25391","74.84184","0.00464"
"14.40000","0.12019","832.02228","75.36433","0.00473"
"14.68800","0.12256","837.02234","75.81724","0.00483"
"14.97600","0.12512","842.62134","76.32439","0.00493"
"15.26400","0.12712","843.78088","76.42943","0.00500"
"15.55200","0.12975","850.05182","76.99744","0.00511"
"15.84000","0.13219","854.97125","77.44305","0.00520"
"16.12800","0.13462","859.59583","77.86194","0.00530"
"16.41600","0.13712","863.56384","78.22136","0.00540"
"16.70400","0.13912","864.13940","78.27350","0.00548"
"16.99200","0.14181","869.44659","78.75422","0.00558"
"17.28000","0.14412","872.72357","79.05105","0.00567"
"17.56800","0.14662","877.27814","79.46360","0.00577"
"17.85600","0.14912","880.65265","79.76926","0.00587"
"18.14400","0.15119","880.67828","79.77158","0.00595"
"18.43200","0.15375","884.34314","80.10355","0.00605"
"18.72000","0.15612","887.52777","80.39201","0.00615"
"19.00800","0.15862","891.50568","80.75233","0.00625"
"19.29600","0.16112","894.04059","80.98194","0.00634"
"19.58400","0.16319","893.82074","80.96202","0.00642"
"19.87200","0.16575","896.90442","81.24134","0.00653"
"20.16000","0.16812","899.28711","81.45717","0.00662"
"20.44800","0.17069","903.46637","81.83572","0.00672"
"20.73600","0.17312","905.27106","81.99919","0.00682"
"21.02400","0.17519","904.57642","81.93627","0.00690"
"21.31200","0.17775","907.34216","82.18679","0.00700"
"21.60000","0.18006","908.77118","82.31623","0.00709"
"21.88800","0.18262","912.80780","82.68187","0.00719"
"22.17600","0.18512","914.24493","82.81204","0.00729"
"22.46400","0.18731","913.94885","82.78522","0.00737"
"22.75200","0.18969","915.41644","82.91816","0.00747"
"23.04000","0.19206","916.64355","83.02930","0.00756"
"23.32800","0.19469","920.56866","83.38484","0.00766"
"23.61600","0.19712","921.47540","83.46697","0.00776"
"23.90400","0.19925","921.11218","83.43407","0.00784"
"24.19200","0.20169","922.25208","83.53732","0.00794"
"24.48000","0.20406","923.28534","83.63092","0.00803"
"24.76800","0.20669","926.85504","83.95426","0.00814"
"25.05600","0.20912","927.71838","84.03246","0.00823"
"25.34400","0.21131","927.47260","84.01020","0.00832"
"25.63200","0.21381","928.56830","84.10945","0.00842"
"25.92000","0.21600","928.34613","84.08932","0.00850"
"26.20800","0.21869","932.36731","84.45356","0.00861"
"26.49600","0.22106","932.55566","84.47062","0.00870"
"26.78400","0.22337","933.51453","84.55747","0.00879"
"27.07200","0.22575","933.15894","84.52527","0.00889"
"27.36000","0.22800","933.05090","84.51548","0.00898"
"27.64800","0.23062","936.64203","84.84077","0.00908"
"27.93600","0.23306","936.75812","84.85128","0.00918"
"28.22400","0.23537","937.29047","84.89950","0.00927"
"28.51200","0.23775","937.24066","84.89499","0.00936"
"28.80000","0.24000","937.12231","84.88427","0.00945"
"29.08800","0.24262","940.23047","85.16580","0.00955"
"29.37600","0.24500","940.15387","85.15887","0.00965"
"29.66400","0.24744","940.99268","85.23484","0.00974"
"29.95200","0.24981","940.90375","85.22679","0.00984"
"30.24000","0.25194","939.68732","85.11661","0.00992"
"30.52800","0.25462","943.07440","85.42341","0.01002"
"30.81600","0.25700","943.03461","85.41980","0.01012"
"31.10400","0.25950","944.85132","85.58436","0.01022"
"31.39200","0.26175","943.46106","85.45843","0.01031"
"31.68000","0.26394","942.71234","85.39061","0.01039"
"31.96800","0.26662","945.69421","85.66071","0.01050"
"32.25600","0.26900","945.24072","85.61963","0.01059"
"32.54400","0.27150","947.64929","85.83780","0.01069"
"32.83200","0.27375","945.95996","85.68478","0.01078"
"33.12000","0.27594","945.10510","85.60735","0.01086"
"33.40800","0.27862","947.43585","85.81847","0.01097"
"33.69600","0.28094","946.96210","85.77555","0.01106"
"33.98400","0.28356","950.05530","86.05573","0.01116"
"34.27200","0.28587","948.38568","85.90450","0.01125"
"34.56000","0.28794","946.74268","85.75568","0.01134"
"34.84800","0.29062","949.43903","85.99991","0.01144"
"35.13600","0.29294","948.46564","85.91174","0.01153"
"35.42400","0.29562","952.36487","86.26493","0.01164"
"35.71200","0.29781","949.52441","86.00764","0.01172"
"36.00000","0.29994","948.66138","85.92947","0.01181"
"36.28800","0.30262","950.85455","86.12813","0.01191"
"36.57600","0.30487","949.35333","85.99215","0.01200"
"36.86400","0.30756","953.28802","86.34856","0.01211"
"37.15200","0.30975","950.62134","86.10700","0.01219"
"37.44000","0.31200","950.05426","86.05564","0.01228"
"37.72800","0.31456","951.76532","86.21062","0.01238"
"38.01600","0.31687","950.50555","86.09652","0.01248"
"38.30400","0.31962","954.71069","86.47742","0.01258"
"38.59200","0.32187","952.54907","86.28162","0.01267"
"38.88000","0.32394","950.78601","86.12193","0.01275"
"39.16800","0.32662","952.99622","86.32212","0.01286"
"39.45600","0.32887","951.11969","86.15215","0.01295"
"39.74400","0.33156","955.14276","86.51656","0.01305"
"40.03200","0.33381","952.77887","86.30244","0.01314"
"40.32000","0.33600","951.71417","86.20599","0.01323"
"40.60800","0.33862","953.45892","86.36404","0.01333"
"40.89600","0.34081","951.45398","86.18243","0.01342"
"41.18400","0.34362","956.10956","86.60413","0.01353"
"41.47200","0.34587","954.00934","86.41389","0.01362"
"41.76000","0.34806","952.75061","86.29987","0.01370"
"42.04800","0.35062","953.73157","86.38873","0.01380"
"42.33600","0.35281","952.04895","86.23632","0.01389"
"42.62400","0.35556","955.71942","86.56879","0.01400"
"42.91200","0.35794","954.85413","86.49041","0.01409"
"43.20000","0.36006","953.20428","86.34097","0.01418"
"43.48800","0.36262","954.22668","86.43358","0.01428"
"43.77600","0.36481","952.37347","86.26572","0.01436"
"44.06400","0.36750","955.58472","86.55659","0.01447"
"44.35200","0.36987","954.81500","86.48687","0.01456"
"44.64000","0.37200","953.31659","86.35114","0.01465"
"44.92800","0.37469","954.74695","86.48071","0.01475"
"45.21600","0.37675","952.08838","86.23989","0.01483"
"45.50400","0.37944","955.28790","86.52970","0.01494"
"45.79200","0.38187","955.26648","86.52776","0.01503"
"46.08000","0.38412","954.05774","86.41827","0.01512"
"46.36800","0.38662","954.57526","86.46515","0.01522"
"46.65600","0.38875","952.13361","86.24399","0.01531"
"46.94400","0.39144","954.87366","86.49218","0.01541"
"47.23200","0.39387","954.83295","86.48849","0.01551"
"47.52000","0.39612","954.08380","86.42063","0.01560"
"47.80800","0.39869","954.55658","86.46346","0.01570"
"48.09600","0.40075","952.05615","86.23697","0.01578"
"48.38400","0.40344","954.12146","86.42405","0.01588"
"48.67200","0.40587","954.67993","86.47463","0.01598"
"48.96000","0.40812","954.37195","86.44673","0.01607"
"49.24800","0.41075","954.58032","86.46561","0.01617"
"49.53600","0.41275","951.70856","86.20548","0.01625"
"49.82400","0.41537","953.43457","86.36182","0.01635"
"50.11200","0.41781","954.64374","86.47135","0.01645"
"50.40000","0.42019","954.50525","86.45881","0.01654"
"50.68800","0.42269","954.06549","86.41898","0.01664"
"50.97600","0.42475","951.62140","86.19759","0.01672"
"51.26400","0.42737","953.22083","86.34247","0.01683"
"51.55200","0.42981","953.60046","86.37685","0.01692"
"51.84000","0.43219","954.43018","86.45201","0.01702"
"52.12800","0.43469","953.56171","86.37334","0.01711"
"52.41600","0.43675","951.31665","86.16999","0.01719"
"52.70400","0.43937","952.49304","86.27654","0.01730"
"52.99200","0.44175","952.67639","86.29315","0.01739"
"53.28000","0.44425","953.97272","86.41058","0.01749"
"53.56800","0.44675","953.59869","86.37669","0.01759"
"53.85600","0.44875","950.51404","86.09729","0.01767"
"54.14400","0.45137","951.97687","86.22979","0.01777"
"54.43200","0.45375","952.25342","86.25484","0.01786"
"54.72000","0.45625","953.77173","86.39236","0.01796"
"55.00800","0.45875","953.03766","86.32587","0.01806"
"55.29600","0.46081","950.44867","86.09136","0.01814"
"55.58400","0.46337","951.41559","86.17895","0.01824"
"55.87200","0.46569","951.02930","86.14396","0.01833"
"56.16000","0.46825","953.13043","86.33428","0.01844"
"56.44800","0.47075","952.55841","86.28246","0.01853"
"56.73600","0.47281","950.06146","86.05629","0.01861"
"57.02400","0.47531","950.34344","86.08183","0.01871"
"57.31200","0.47769","950.30731","86.07856","0.01881"
"57.60000","0.48025","952.58514","86.28489","0.01891"
"57.88800","0.48275","951.80981","86.21466","0.01901"
"58.17600","0.48481","949.48730","86.00429","0.01909"
"58.46400","0.48737","949.83710","86.03597","0.01919"
"58.75200","0.48969","949.27179","85.98476","0.01928"
"59.04000","0.49231","951.66156","86.20123","0.01938"
"59.32800","0.49469","951.09644","86.15004","0.01948"
"59.61600","0.49681","948.82416","85.94421","0.01956"
"59.90400","0.49937","949.03491","85.96331","0.01966"
"60.19200","0.50162","948.14172","85.88240","0.01975"
"60.48000","0.50425","950.74725","86.11841","0.01985"
"60.76800","0.50675","950.18622","86.06759","0.01995"
"61.05600","0.50887","948.46887","85.91203","0.02003"
"61.34400","0.51131","947.76526","85.84830","0.02013"
"61.63200","0.51362","947.36133","85.81171","0.02022"
"61.92000","0.51625","949.96130","86.04722","0.02032"
"62.20800","0.51869","948.90936","85.95193","0.02042"
"62.49600","0.52094","947.57623","85.83118","0.02051"
"62.78400","0.52337","947.33752","85.80956","0.02061"
"63.07200","0.52562","946.22803","85.70906","0.02069"
"63.36000","0.52825","948.47101","85.91223","0.02080"
"63.64800","0.53069","947.79150","85.85068","0.02089"
"63.93600","0.53300","947.24194","85.80090","0.02098"
"64.22400","0.53537","946.14642","85.70167","0.02108"
"64.51200","0.53756","944.72223","85.57266","0.02116"
"64.80000","0.54025","947.30389","85.80651","0.02127"
"65.08800","0.54262","946.35437","85.72050","0.02136"
"65.37600","0.54506","946.73456","85.75494","0.02146"
"65.66400","0.54731","944.84790","85.58405","0.02155"
"65.95200","0.54956","943.81708","85.49068","0.02164"
"66.24000","0.55225","946.30688","85.71620","0.02174"
"66.52800","0.55462","944.75085","85.57526","0.02184"
"66.81600","0.55706","945.76788","85.66738","0.02193"
"67.10400","0.55931","943.35803","85.44910","0.02202"
"67.39200","0.56156","942.77386","85.39619","0.02211"
"67.68000","0.56419","944.57043","85.55891","0.02221"
"67.96800","0.56656","943.34473","85.44789","0.02231"
"68.25600","0.56912","944.94409","85.59277","0.02241"
"68.54400","0.57137","942.82745","85.40104","0.02250"
"68.83200","0.57356","940.99091","85.23468","0.02258"
"69.12000","0.57619","943.20282","85.43504","0.02268"
"69.40800","0.57856","941.83246","85.31091","0.02278"
"69.69600","0.58119","944.39301","85.54285","0.02288"
"69.98400","0.58337","941.21063","85.25459","0.02297"
"70.27200","0.58556","939.80786","85.12753","0.02305"
"70.56000","0.58825","941.97906","85.32419","0.02316"
"70.84800","0.59050","940.04718","85.14920","0.02325"
"71.13600","0.59325","943.39801","85.45272","0.02336"
"71.42400","0.59544","939.98492","85.14356","0.02344"
"71.71200","0.59756","938.73163","85.03004","0.02353"
"72.00000","0.60019","939.80786","85.12753","0.02363"
"72.28800","0.60250","938.68842","85.02612","0.02372"
"72.57600","0.60525","942.22827","85.34676","0.02383"
"72.86400","0.60744","938.89807","85.04511","0.02391"
"73.15200","0.60956","936.96545","84.87006","0.02400"
"73.44000","0.61219","938.53741","85.01244","0.02410"
"73.72800","0.61450","936.81116","84.85609","0.02419"
"74.01600","0.61725","940.72131","85.21027","0.02430"
"74.30400","0.61944","937.45746","84.91463","0.02439"
"74.59200","0.62150","934.98798","84.69094","0.02447"
"74.88000","0.62425","937.10876","84.88304","0.02458"
"75.16800","0.62644","934.81244","84.67504","0.02466"
"75.45600","0.62919","938.55493","85.01403","0.02477"
"75.74400","0.63150","936.12744","84.79415","0.02486"
"76.03200","0.63362","933.97516","84.59920","0.02495"
"76.32000","0.63619","935.21240","84.71127","0.02505"
"76.60800","0.63837","932.95581","84.50687","0.02513"
"76.89600","0.64119","936.66992","84.84329","0.02524"
"77.18400","0.64350","934.54279","84.65061","0.02533"
"77.47200","0.64556","932.20538","84.43890","0.02542"
"77.76000","0.64825","933.49609","84.55581","0.02552"
"78.04800","0.65037","930.99603","84.32935","0.02561"
"78.33600","0.65312","934.22375","84.62172","0.02571"
"78.62400","0.65550","932.97687","84.50877","0.02581"
"78.91200","0.65762","930.63190","84.29637","0.02589"
"79.20000","0.66025","931.33801","84.36033","0.02599"
"79.48800","0.66237","928.75732","84.12657","0.02608"
"79.77600","0.66512","931.72852","84.39570","0.02619"
"80.06400","0.66750","931.05389","84.33459","0.02628"
"80.35200","0.66969","928.99182","84.14781","0.02637"
"80.64000","0.67219","929.05664","84.15368","0.02646"
"80.92800","0.67437","926.69342","83.93962","0.02655"
"81.21600","0.67706","929.34460","84.17976","0.02666"
"81.50400","0.67950","929.09985","84.15759","0.02675"
"81.79200","0.68169","927.12177","83.97842","0.02684"
"82.08000","0.68419","926.77234","83.94677","0.02694"
"82.36800","0.68637","924.74670","83.76329","0.02702"
"82.65600","0.68906","926.55298","83.92690","0.02713"
"82.94400","0.69144","926.50073","83.92216","0.02722"
"83.23200","0.69369","925.29163","83.81264","0.02731"
"83.52000","0.69625","924.94263","83.78104","0.02741"
"83.80800","0.69831","922.21198","83.53369","0.02749"
"84.09600","0.70100","924.33569","83.72606","0.02760"
"84.38400","0.70344","924.43079","83.73467","0.02769"
"84.67200","0.70581","923.49976","83.65034","0.02779"
"84.96000","0.70825","922.69525","83.57747","0.02788"
"85.24800","0.71037","920.04517","83.33743","0.02797"
"85.53600","0.71306","921.89636","83.50510","0.02807"
"85.82400","0.71537","921.25519","83.44703","0.02816"
"86.11200","0.71781","921.63141","83.48111","0.02826"
"86.40000","0.72025","920.37872","83.36764","0.02836"
"86.68800","0.72237","917.97467","83.14988","0.02844"
"86.97600","0.72500","919.05969","83.24816","0.02854"
"87.26400","0.72737","918.81061","83.22560","0.02864"
"87.55200","0.72981","919.44867","83.28339","0.02873"
"87.84000","0.73231","918.45032","83.19296","0.02883"
"88.12800","0.73431","915.44995","82.92119","0.02891"
"88.41600","0.73700","916.60626","83.02593","0.02902"
"88.70400","0.73937","916.23346","82.99216","0.02911"
"88.99200","0.74187","917.66107","83.12148","0.02921"
"89.28000","0.74431","916.10114","82.98018","0.02930"
"89.56800","0.74631","913.27301","82.72401","0.02938"
"89.85600","0.74900","914.10413","82.79929","0.02949"
"90.14400","0.75137","913.45667","82.74064","0.02958"
"90.43200","0.75381","914.79114","82.86152","0.02968"
"90.72000","0.75631","913.85535","82.77676","0.02978"
"91.00800","0.75837","910.90436","82.50945","0.02986"
"91.29600","0.76094","910.82892","82.50262","0.02996"
"91.58400","0.76331","911.17035","82.53355","0.03005"
"91.87200","0.76587","913.08746","82.70720","0.03015"
"92.16000","0.76837","911.63611","82.57574","0.03025"
"92.44800","0.77037","908.51074","82.29264","0.03033"
"92.73600","0.77294","908.56439","82.29750","0.03043"
"93.02400","0.77531","908.46045","82.28809","0.03052"
"93.31200","0.77787","910.00134","82.42766","0.03062"
"93.60000","0.78037","908.96497","82.33379","0.03072"
"93.88800","0.78244","905.82410","82.04929","0.03080"
"94.17600","0.78494","906.05182","82.06991","0.03090"
"94.46400","0.78725","905.23950","81.99633","0.03099"
"94.75200","0.78981","907.12439","82.16706","0.03109"
"95.04000","0.79231","906.05951","82.07061","0.03119"
"95.32800","0.79444","903.89661","81.87469","0.03128"
"95.61600","0.79694","903.33270","81.82362","0.03138"
"95.90400","0.79925","902.38049","81.73737","0.03147"
"96.19200","0.80181","904.58148","81.93673","0.03157"
"96.48000","0.80431","903.22430","81.81380","0.03167"
"96.76800","0.80644","901.37006","81.64584","0.03175"
"97.05600","0.80887","900.57227","81.57358","0.03185"
"97.34400","0.81125","899.82141","81.50556","0.03194"
"97.63200","0.81381","901.69580","81.67535","0.03204"
"97.92000","0.81631","900.60681","81.57671","0.03214"
"98.20800","0.81850","899.21698","81.45081","0.03222"
"98.49600","0.82094","897.96790","81.33767","0.03232"
"98.78400","0.82319","896.96570","81.24689","0.03241"
"99.07200","0.82581","899.13782","81.44364","0.03251"
"99.36000","0.82825","897.64392","81.30833","0.03261"
"99.64800","0.83062","897.28430","81.27575","0.03270"
"99.93600","0.83294","895.36084","81.10152","0.03279"
"100.22400","0.83519","894.35168","81.01012","0.03288"
"100.51200","0.83787","896.56396","81.21050","0.03299"
"100.80000","0.84025","894.71436","81.04297","0.03308"
"101.08800","0.84269","895.17841","81.08500","0.03318"
"101.37600","0.84494","892.48468","80.84100","0.03327"
"101.66400","0.84719","891.29175","80.73295","0.03335"
"101.95200","0.84981","893.06757","80.89380","0.03346"
"102.24000","0.85219","891.74139","80.77367","0.03355"
"102.52800","0.85475","893.48761","80.93185","0.03365"
"102.81600","0.85700","889.75031","80.59332","0.03374"
"103.10400","0.85912","888.47272","80.47760","0.03382"
"103.39200","0.86175","890.09338","80.62440","0.03393"
"103.68000","0.86419","888.86578","80.51321","0.03402"
"103.96800","0.86681","890.90576","80.69798","0.03413"
"104.25600","0.86894","887.14899","80.35770","0.03421"
"104.54400","0.87112","885.64648","80.22160","0.03430"
"104.83200","0.87381","887.98822","80.43372","0.03440"
"105.12000","0.87612","885.81323","80.23671","0.03449"
"105.40800","0.87875","888.15930","80.44921","0.03460"
"105.69600","0.88100","885.04340","80.16698","0.03469"
"105.98400","0.88319","883.28131","80.00736","0.03477"
"106.27200","0.88581","884.80347","80.14524","0.03487"
"106.56000","0.88812","883.01727","79.98345","0.03497"
"106.84800","0.89081","886.02362","80.25576","0.03507"
"107.13600","0.89306","882.89325","79.97221","0.03516"
"107.42400","0.89512","880.18573","79.72697","0.03524"
"107.71200","0.89781","881.97961","79.88946","0.03535"
"108.00000","0.90012","879.85004","79.69656","0.03544"
"108.28800","0.90281","883.28040","80.00729","0.03554"
"108.57600","0.90506","880.44202","79.75018","0.03563"
"108.86400","0.90712","877.69934","79.50175","0.03571"
"109.15200","0.90981","879.45471","79.66075","0.03582"
"109.44000","0.91206","876.81866","79.42198","0.03591"
"109.72800","0.91481","880.46753","79.75249","0.03602"
"110.01600","0.91706","877.46753","79.48075","0.03610"
"110.30400","0.91912","875.08417","79.26487","0.03619"
"110.59200","0.92181","876.29230","79.37431","0.03629"
"110.88000","0.92406","874.26483","79.19066","0.03638"
"111.16800","0.92681","877.80505","79.51133","0.03649"
"111.45600","0.92912","875.28809","79.28334","0.03658"
"111.74400","0.93119","872.38123","79.02004","0.03666"
"112.03200","0.93375","873.54370","79.12534","0.03676"
"112.32000","0.93600","871.24249","78.91689","0.03685"
"112.60800","0.93875","874.44635","79.20710","0.03696"
"112.89600","0.94106","872.68268","79.04735","0.03705"
"113.18400","0.94319","870.13385","78.81647","0.03713"
"113.47200","0.94581","870.71533","78.86914","0.03724"
"113.76000","0.94800","868.28729","78.64921","0.03732"
"114.04800","0.95075","871.61108","78.95028","0.03743"
"114.33600","0.95306","870.00903","78.80517","0.03752"
"114.62400","0.95525","867.95288","78.61892","0.03761"
"114.91200","0.95775","867.70001","78.59602","0.03771"
"115.20000","0.96000","865.35986","78.38405","0.03780"
"115.48800","0.96275","868.46417","78.66523","0.03790"
"115.77600","0.96506","866.95355","78.52840","0.03799"
"116.06400","0.96725","865.05164","78.35612","0.03808"
"116.35200","0.96981","865.31958","78.38039","0.03818"
"116.64000","0.97200","862.67163","78.14055","0.03827"
"116.92800","0.97469","865.06036","78.35692","0.03837"
"117.21600","0.97706","864.11005","78.27084","0.03847"
"117.50400","0.97925","862.88434","78.15981","0.03855"
"117.79200","0.98187","862.23956","78.10141","0.03866"
"118.08000","0.98394","859.80389","77.88079","0.03874"
"118.36800","0.98662","861.80902","78.06241","0.03884"
"118.65600","0.98906","861.41351","78.02659","0.03894"
"118.94400","0.99131","860.43097","77.93759","0.03903"
"119.23200","0.99381","859.56476","77.85912","0.03913"
"119.52000","0.99594","857.21985","77.64673","0.03921"
"119.80800","0.99869","859.40387","77.84455","0.03932"
"120.09600","1.00100","858.00330","77.71769","0.03941"
"120.38400","1.00331","857.45508","77.66803","0.03950"
"120.67200","1.00581","857.12512","77.63815","0.03960"
"120.96000","1.00794","854.46210","77.39693","0.03968"
"121.24800","1.01062","855.61310","77.50119","0.03979"
"121.53600","1.01300","855.58948","77.49905","0.03988"
"121.82400","1.01537","855.16901","77.46096","0.03998"
"122.11200","1.01794","854.52924","77.40301","0.04008"
"122.40000","1.01994","851.34991","77.11503","0.04016"
"122.68800","1.02262","852.93988","77.25905","0.04026"
"122.97600","1.02500","852.40845","77.21091","0.04035"
"123.26400","1.02744","853.02100","77.26640","0.04045"
"123.55200","1.02994","851.78625","77.15455","0.04055"
"123.84000","1.03194","848.50500","76.85734","0.04063"
"124.12800","1.03462","849.41119","76.93942","0.04073"
"124.41600","1.03694","848.92633","76.89550","0.04082"
"124.70400","1.03937","850.04810","76.99711","0.04092"
"124.99200","1.04194","849.08551","76.90992","0.04102"
"125.28000","1.04394","845.86859","76.61853","0.04110"
"125.56800","1.04656","846.30670","76.65822","0.04120"
"125.85600","1.04894","846.21228","76.64967","0.04130"
"126.14400","1.05137","847.04596","76.72517","0.04139"
"126.43200","1.05400","846.85150","76.70757","0.04150"
"126.72000","1.05594","842.84900","76.34502","0.04157"
"127.00800","1.05856","843.62634","76.41543","0.04168"
"127.29600","1.06094","843.68427","76.42068","0.04177"
"127.58400","1.06344","844.66022","76.50908","0.04187"
"127.87200","1.06594","843.89801","76.44004","0.04197"
"128.16000","1.06794","840.41907","76.12492","0.04204"
"128.44800","1.07056","840.55579","76.13730","0.04215"
"128.73600","1.07287","839.76117","76.06532","0.04224"
"129.02400","1.07544","841.96906","76.26531","0.04234"
"129.31200","1.07800","840.95959","76.17387","0.04244"
"129.60000","1.08000","838.00079","75.90587","0.04252"
"129.88800","1.08256","837.62537","75.87186","0.04262"
"130.17600","1.08487","837.31299","75.84357","0.04271"
"130.46400","1.08744","838.99402","75.99583","0.04281"
"130.75200","1.08994","837.53949","75.86408","0.04291"
"131.04000","1.09200","835.16638","75.64913","0.04299"
"131.32800","1.09456","834.36053","75.57613","0.04309"
"131.61600","1.09687","833.91827","75.53608","0.04318"
"131.90400","1.09937","835.26849","75.65838","0.04328"
"132.19200","1.10187","834.70874","75.60767","0.04338"
"132.48000","1.10412","832.80530","75.43526","0.04347"
"132.76800","1.10650","831.38055","75.30621","0.04356"
"133.05600","1.10881","830.68933","75.24360","0.04365"
"133.34400","1.11144","832.61115","75.41768","0.04376"
"133.63200","1.11387","831.46588","75.31394","0.04385"
"133.92000","1.11619","830.69354","75.24398","0.04394"
"134.20800","1.11856","828.43604","75.03950","0.04404"
"134.49600","1.12081","827.51068","74.95568","0.04413"
"134.78400","1.12344","830.03027","75.18390","0.04423"
"135.07200","1.12587","828.07953","75.00720","0.04433"
"135.36000","1.12819","827.76929","74.97910","0.04442"
"135.64800","1.13050","825.56696","74.77962","0.04451"
"135.93600","1.13281","824.73047","74.70385","0.04460"
"136.22400","1.13544","826.47150","74.86155","0.04470"
"136.51200","1.13781","825.19708","74.74611","0.04480"
"136.80000","1.14019","825.10834","74.73808","0.04489"
"137.08800","1.14256","822.79712","74.52872","0.04498"
"137.37600","1.14475","821.39252","74.40150","0.04507"
"137.66400","1.14744","823.85291","74.62436","0.04517"
"137.95200","1.14981","821.91125","74.44849","0.04527"
"138.24000","1.15231","822.79730","74.52874","0.04537"
"138.52800","1.15456","820.01898","74.27708","0.04546"
"138.81600","1.15675","818.57660","74.14643","0.04554"
"139.10400","1.15944","820.27942","74.30067","0.04565"
"139.39200","1.16175","818.30585","74.12191","0.04574"
"139.68000","1.16431","820.19324","74.29287","0.04584"
"139.96800","1.16656","817.16815","74.01885","0.04593"
"140.25600","1.16875","815.35944","73.85502","0.04601"
"140.54400","1.17137","817.08087","74.01095","0.04612"
"140.83200","1.17375","815.49829","73.86760","0.04621"
"141.12000","1.17637","817.73047","74.06979","0.04631"
"141.40800","1.17862","814.22552","73.75231","0.04640"
"141.69600","1.18075","812.30823","73.57864","0.04649"
"141.98400","1.18344","814.35199","73.76377","0.04659"
"142.27200","1.18575","812.35541","73.58292","0.04668"
"142.56000","1.18837","814.85547","73.80937","0.04679"
"142.84800","1.19056","811.37653","73.49425","0.04687"
"143.13600","1.19275","809.23492","73.30026","0.04696"
"143.42400","1.19544","810.86469","73.44789","0.04706"
"143.71200","1.19769","808.57166","73.24019","0.04715"
"144.00000","1.20037","811.74121","73.52728","0.04726"
"144.28800","1.20262","808.59314","73.24213","0.04735"
"144.57600","1.20475","806.50275","73.05279","0.04743"
"144.86400","1.20737","807.45825","73.13934","0.04753"
"145.15200","1.20969","805.54504","72.96603","0.04763"
"145.44000","1.21237","808.43719","73.22800","0.04773"
"145.72800","1.21469","806.00281","73.00750","0.04782"
"146.01600","1.21675","803.10522","72.74504","0.04790"
"146.30400","1.21944","804.60040","72.88047","0.04801"
"146.59200","1.22169","802.30945","72.67296","0.04810"
"146.88000","1.22437","805.56030","72.96742","0.04820"
"147.16800","1.22662","802.65405","72.70417","0.04829"
"147.45600","1.22875","800.41400","72.50127","0.04838"
"147.74400","1.23144","801.20880","72.57326","0.04848"
"148.03200","1.23362","798.74292","72.34990","0.04857"
"148.32000","1.23631","802.10883","72.65479","0.04867"
"148.60800","1.23862","799.65674","72.43268","0.04876"
"148.89600","1.24081","797.69104","72.25462","0.04885"
"149.18400","1.24337","797.66223","72.25201","0.04895"
"149.47200","1.24562","795.78308","72.08180","0.04904"
"149.76000","1.24837","799.18347","72.38981","0.04915"
"150.04800","1.25069","796.52069","72.14861","0.04924"
"150.33600","1.25281","794.33459","71.95060","0.04932"
"150.62400","1.25537","794.55414","71.97048","0.04942"
"150.91200","1.25762","792.40222","71.77557","0.04951"
"151.20000","1.26031","794.80859","71.99353","0.04962"
"151.48800","1.26262","793.03320","71.83272","0.04971"
"151.77600","1.26481","791.42767","71.68729","0.04980"
"152.06400","1.26737","791.16028","71.66307","0.04990"
"152.35200","1.26956","788.97693","71.46530","0.04998"
"152.64000","1.27231","791.66534","71.70882","0.05009"
"152.92800","1.27462","789.78601","71.53859","0.05018"
"153.21600","1.27687","788.68866","71.43919","0.05027"
"153.50400","1.27944","788.19208","71.39421","0.05037"
"153.79200","1.28156","785.52655","71.15277","0.05046"
"154.08000","1.28425","787.74261","71.35350","0.05056"
"154.36800","1.28662","786.72076","71.26094","0.05065"
"154.65600","1.28887","785.69501","71.16803","0.05074"
"154.94400","1.29150","785.47473","71.14807","0.05085"
"155.23200","1.29356","782.43158","70.87243","0.05093"
"155.52000","1.29625","783.90894","71.00624","0.05103"
"155.80800","1.29862","783.36530","70.95700","0.05113"
"156.09600","1.30094","782.51312","70.87981","0.05122"
"156.38400","1.30350","782.34070","70.86420","0.05132"
"156.67200","1.30550","778.75989","70.53985","0.05140"
"156.96000","1.30825","780.34839","70.68373","0.05151"
"157.24800","1.31062","780.10254","70.66146","0.05160"
"157.53600","1.31300","779.49512","70.60645","0.05169"
"157.82400","1.31550","778.63239","70.52830","0.05179"
"158.11200","1.31750","775.72992","70.26539","0.05187"
"158.40000","1.32025","777.11340","70.39071","0.05198"
"158.68800","1.32256","776.18744","70.30683","0.05207"
"158.97600","1.32494","776.57257","70.34172","0.05216"
"159.26400","1.32750","775.49878","70.24445","0.05226"
"159.55200","1.32956","772.15216","69.94132","0.05234"
"159.84000","1.33219","772.80255","70.00023","0.05245"
"160.12800","1.33456","773.07153","70.02460","0.05254"
"160.41600","1.33700","773.21643","70.03772","0.05264"
"160.70400","1.33956","772.31555","69.95612","0.05274"
"160.99200","1.34150","768.66101","69.62509","0.05281"
"161.28000","1.34419","769.47754","69.69905","0.05292"
"161.56800","1.34656","769.09784","69.66466","0.05301"
"161.85600","1.34900","769.83234","69.73119","0.05311"
"162.14400","1.35150","768.88916","69.64576","0.05321"
"162.43200","1.35356","765.72021","69.35872","0.05329"
"162.72000","1.35612","765.31970","69.32243","0.05339"
"163.00800","1.35850","764.84747","69.27966","0.05348"
"163.29600","1.36100","766.36554","69.41717","0.05358"
"163.58400","1.36350","765.34033","69.32430","0.05368"
"163.87200","1.36556","762.52271","69.06908","0.05376"
"164.16000","1.36812","761.56824","68.98263","0.05386"
"164.44800","1.37050","761.95630","69.01778","0.05396"
"164.73600","1.37306","763.33514","69.14268","0.05406"
"165.02400","1.37556","761.86188","69.00923","0.05416"
"165.31200","1.37756","758.98413","68.74857","0.05423"
"165.60000","1.38012","758.23108","68.68035","0.05434"
"165.88800","1.38250","757.81146","68.64234","0.05443"
"166.17600","1.38500","759.33704","68.78053","0.05453"
"166.46400","1.38750","758.06158","68.66500","0.05463"
"166.75200","1.38962","755.60718","68.44268","0.05471"
"167.04000","1.39212","754.38367","68.33186","0.05481"
"167.32800","1.39444","753.66443","68.26671","0.05490"
"167.61600","1.39706","755.84564","68.46428","0.05500"
"167.90400","1.39950","754.32117","68.32619","0.05510"
"168.19200","1.40169","752.52948","68.16390","0.05518"
"168.48000","1.40412","750.67194","67.99564","0.05528"
"168.76800","1.40644","750.08044","67.94207","0.05537"
"169.05600","1.40906","752.08258","68.12342","0.05547"
"169.34400","1.41150","750.35840","67.96725","0.05557"
"169.63200","1.41375","749.45129","67.88508","0.05566"
"169.92000","1.41612","747.27332","67.68780","0.05575"
"170.20800","1.41844","746.19830","67.59042","0.05584"
"170.49600","1.42106","748.17889","67.76983","0.05595"
"170.78400","1.42344","746.53613","67.62103","0.05604"
"171.07200","1.42581","746.15723","67.58671","0.05613"
"171.36000","1.42812","743.55719","67.35120","0.05623"
"171.64800","1.43037","742.22864","67.23086","0.05631"
"171.93600","1.43306","744.35870","67.42380","0.05642"
"172.22400","1.43544","743.01538","67.30212","0.05651"
"172.51200","1.43787","742.63312","67.26749","0.05661"
"172.80000","1.44012","739.60211","66.99294","0.05670"
"173.08800","1.44237","738.56500","66.89900","0.05679"
"173.37600","1.44506","740.44061","67.06889","0.05689"
"173.66400","1.44737","738.53668","66.89644","0.05698"
"173.95200","1.44981","738.62561","66.90450","0.05708"
"174.24000","1.45212","736.25958","66.69018","0.05717"
"174.52800","1.45437","734.41064","66.52271","0.05726"
"174.81600","1.45700","736.10919","66.67656","0.05736"
"175.10400","1.45937","734.81140","66.55901","0.05746"
"175.39200","1.46187","735.31677","66.60478","0.05755"
"175.68000","1.46425","732.77966","66.37497","0.05765"
"175.96800","1.46631","730.44391","66.16340","0.05773"
"176.25600","1.46906","732.12787","66.31593","0.05784"
"176.54400","1.47137","730.19989","66.14130","0.05793"
"176.83200","1.47400","732.21472","66.32380","0.05803"
"177.12000","1.47619","729.00916","66.03344","0.05812"
"177.40800","1.47831","726.90759","65.84308","0.05820"
"177.69600","1.48106","727.92725","65.93544","0.05831"
"177.98400","1.48337","726.06006","65.76631","0.05840"
"178.27200","1.48594","727.96295","65.93867","0.05850"
"178.56000","1.48819","724.97430","65.66796","0.05859"
"178.84800","1.49037","723.04974","65.49364","0.05868"
"179.13600","1.49300","723.54956","65.53891","0.05878"
"179.42400","1.49531","721.86096","65.38596","0.05887"
"179.71200","1.49794","724.32965","65.60957","0.05897"
"180.00000","1.50025","721.17590","65.32391","0.05906"
"180.28800","1.50231","718.46771","65.07860","0.05915"
"180.57600","1.50500","719.49335","65.17150","0.05925"
"180.86400","1.50731","717.40717","64.98254","0.05934"
"181.15200","1.51000","720.49158","65.26192","0.05945"
"181.44000","1.51219","716.94153","64.94035","0.05953"
"181.72800","1.51437","714.91089","64.75642","0.05962"
"182.01600","1.51700","715.16077","64.77905","0.05972"
"182.30400","1.51925","712.91443","64.57558","0.05981"
"182.59200","1.52200","716.48468","64.89897","0.05992"
"182.88000","1.52425","712.66669","64.55314","0.06001"
"183.16800","1.52637","710.93414","64.39621","0.06009"
"183.45600","1.52900","710.91144","64.39415","0.06020"
"183.74400","1.53125","708.88507","64.21060","0.06029"
"184.03200","1.53394","711.80945","64.47549","0.06039"
"184.32000","1.53625","709.29889","64.24809","0.06048"
"184.60800","1.53837","706.94141","64.03455","0.06057"
"184.89600","1.54100","707.19135","64.05719","0.06067"
"185.18400","1.54319","704.43079","63.80714","0.06076"
"185.47200","1.54594","707.07764","64.04689","0.06086"
"185.76000","1.54825","704.63855","63.82595","0.06095"
"186.04800","1.55037","702.87408","63.66613","0.06104"
"186.33600","1.55306","703.16687","63.69265","0.06114"
"186.62400","1.55519","699.53235","63.36344","0.06123"
"186.91200","1.55794","702.90991","63.66938","0.06134"
"187.20000","1.56025","700.71008","63.47012","0.06143"
"187.48800","1.56250","699.18219","63.33172","0.06152"
"187.77600","1.56500","698.01154","63.22568","0.06161"
"188.06400","1.56719","695.58942","63.00629","0.06170"
"188.35200","1.56994","697.89929","63.21552","0.06181"
"188.64000","1.57225","696.31024","63.07158","0.06190"
"188.92800","1.57444","694.59485","62.91620","0.06199"
"189.21600","1.57706","694.18958","62.87949","0.06209"
"189.50400","1.57912","690.93982","62.58513","0.06217"
"189.79200","1.58187","692.83160","62.75648","0.06228"
"190.08000","1.58425","691.90051","62.67215","0.06237"
"190.36800","1.58644","690.22064","62.51999","0.06246"
"190.65600","1.58906","689.75934","62.47820","0.06256"
"190.94400","1.59112","686.47864","62.18104","0.06264"
"191.23200","1.59394","688.29755","62.34579","0.06275"
"191.52000","1.59625","687.15869","62.24263","0.06284"
"191.80800","1.59856","686.66193","62.19764","0.06294"
"192.09600","1.60106","685.43280","62.08630","0.06303"
"192.38400","1.60312","682.22028","61.79531","0.06312"
"192.67200","1.60587","682.97101","61.86332","0.06322"
"192.96000","1.60825","682.36517","61.80844","0.06332"
"193.24800","1.61056","682.00433","61.77576","0.06341"
"193.53600","1.61312","680.95190","61.68043","0.06351"
"193.82400","1.61512","677.52667","61.37017","0.06359"
"194.11200","1.61781","677.62390","61.37897","0.06369"
"194.40000","1.62019","677.88232","61.40239","0.06379"
"194.68800","1.62256","677.49005","61.36685","0.06388"
"194.97600","1.62512","676.53357","61.28022","0.06398"
"195.26400","1.62712","672.93683","60.95442","0.06406"
"195.55200","1.62975","672.93683","60.95442","0.06416"
"195.84000","1.63219","673.01825","60.96180","0.06426"
"196.12800","1.63462","672.95789","60.95633","0.06436"
"196.41600","1.63712","671.45105","60.81984","0.06445"
"196.70400","1.63912","668.41913","60.54521","0.06453"
"196.99200","1.64175","668.08441","60.51489","0.06464"
"197.28000","1.64412","667.52252","60.46400","0.06473"
"197.56800","1.64662","668.39166","60.54272","0.06483"
"197.85600","1.64912","666.46210","60.36794","0.06493"
"198.14400","1.65119","663.91400","60.13714","0.06501"
"198.43200","1.65375","663.18542","60.07114","0.06511"
"198.72000","1.65612","662.45367","60.00486","0.06520"
"199.00800","1.65862","663.59644","60.10837","0.06530"
"199.29600","1.66112","661.72614","59.93896","0.06540"
"199.58400","1.66319","658.99396","59.69148","0.06548"
"199.87200","1.66575","658.08740","59.60937","0.06558"
"200.16000","1.66812","657.60559","59.56572","0.06567"
"200.44800","1.67062","658.51331","59.64795","0.06577"
"200.73600","1.67312","657.06366","59.51664","0.06587"
"201.02400","1.67519","654.20599","59.25779","0.06595"
"201.31200","1.67775","652.96747","59.14560","0.06605"
"201.60000","1.68006","652.15375","59.07190","0.06614"
"201.88800","1.68262","653.55310","59.19865","0.06625"
"202.17600","1.68512","652.25568","59.08113","0.06634"
"202.46400","1.68725","649.62823","58.84314","0.06643"
"202.75200","1.68969","647.84509","58.68162","0.06652"
"203.04000","1.69206","647.01318","58.60627","0.06662"
"203.32800","1.69469","648.50562","58.74145","0.06672"
"203.61600","1.69712","646.66418","58.57465","0.06682"
"203.90400","1.69925","644.74426","58.40075","0.06690"
"204.19200","1.70175","642.73022","58.21832","0.06700"
"204.48000","1.70406","641.66583","58.12191","0.06709"
"204.76800","1.70662","643.08026","58.25002","0.06719"
"205.05600","1.70912","641.48779","58.10578","0.06729"
"205.34400","1.71131","639.53821","57.92918","0.06737"
"205.63200","1.71381","637.78973","57.77081","0.06747"
"205.92000","1.71600","635.82831","57.59314","0.06756"
"206.20800","1.71869","637.67981","57.76085","0.06766"
"206.49600","1.72106","635.67487","57.57925","0.06776"
"206.78400","1.72337","634.83240","57.50293","0.06785"
"207.07200","1.72575","632.23682","57.26783","0.06794"
"207.36000","1.72800","630.68976","57.12770","0.06803"
"207.64800","1.73069","632.25427","57.26941","0.06814"
"207.93600","1.73306","630.06262","57.07089","0.06823"
"208.22400","1.73544","629.71930","57.03979","0.06832"
"208.51200","1.73775","627.29822","56.82049","0.06842"
"208.80000","1.74000","625.33954","56.64307","0.06850"
"209.08800","1.74262","626.35248","56.73483","0.06861"
"209.37600","1.74500","624.62665","56.57850","0.06870"
"209.66400","1.74737","624.01385","56.52299","0.06879"
"209.95200","1.74981","622.01892","56.34229","0.06889"
"210.24000","1.75194","619.51385","56.11539","0.06897"
"210.52800","1.75462","620.65643","56.21888","0.06908"
"210.81600","1.75700","618.83655","56.05404","0.06917"
"211.10400","1.75950","619.28735","56.09487","0.06927"
"211.39200","1.76175","615.98755","55.79597","0.06936"
"211.68000","1.76394","613.89410","55.60635","0.06945"
"211.96800","1.76662","615.03571","55.70975","0.06955"
"212.25600","1.76894","612.49335","55.47947","0.06964"
"212.54400","1.77150","613.81818","55.59947","0.06974"
"212.83200","1.77375","610.39233","55.28916","0.06983"
"213.12000","1.77594","608.41895","55.11041","0.06992"
"213.40800","1.77862","608.80670","55.14553","0.07002"
"213.69600","1.78100","606.55005","54.94113","0.07012"
"213.98400","1.78362","608.60645","55.12740","0.07022"
"214.27200","1.78587","605.24292","54.82273","0.07031"
"214.56000","1.78794","602.64862","54.58774","0.07039"
"214.84800","1.79062","603.11505","54.62999","0.07050"
"215.13600","1.79294","600.50586","54.39365","0.07059"
"215.42400","1.79562","602.88568","54.60921","0.07069"
"215.71200","1.79781","598.86493","54.24501","0.07078"
"216.00000","1.79994","596.89899","54.06694","0.07086"
"216.28800","1.80262","597.11670","54.08666","0.07097"
"216.57600","1.80487","594.09601","53.81305","0.07106"
"216.86400","1.80762","597.06854","54.08229","0.07117"
"217.15200","1.80975","593.07275","53.72036","0.07125"
"217.44000","1.81200","590.85095","53.51911","0.07134"
"217.72800","1.81456","590.62848","53.49895","0.07144"
"218.01600","1.81687","587.90210","53.25200","0.07153"
"218.30400","1.81962","590.68237","53.50384","0.07164"
"218.59200","1.82187","587.24072","53.19209","0.07173"
"218.88000","1.82394","584.73193","52.96485","0.07181"
"219.16800","1.82662","584.52405","52.94602","0.07191"
"219.45600","1.82887","581.71490","52.69157","0.07200"
"219.74400","1.83156","584.25946","52.92205","0.07211"
"220.03200","1.83381","580.93616","52.62103","0.07220"
"220.32000","1.83600","578.73560","52.42170","0.07228"
"220.60800","1.83862","578.20081","52.37326","0.07239"
"220.89600","1.84081","575.21252","52.10258","0.07247"
"221.18400","1.84362","578.02826","52.35763","0.07258"
"221.47200","1.84587","574.75928","52.06153","0.07267"
"221.76000","1.84806","572.84827","51.88843","0.07276"
"222.04800","1.85062","571.82947","51.79615","0.07286"
"222.33600","1.85275","568.74969","51.51718","0.07294"
"222.62400","1.85556","570.86157","51.70848","0.07305"
"222.91200","1.85787","568.83759","51.52514","0.07314"
"223.20000","1.86000","566.18274","51.28467","0.07323"
"223.48800","1.86262","565.70685","51.24156","0.07333"
"223.77600","1.86475","562.24780","50.92824","0.07342"
"224.06400","1.86756","563.65308","51.05553","0.07353"
"224.35200","1.86987","562.13367","50.91790","0.07362"
"224.64000","1.87200","559.80908","50.70734","0.07370"
"224.92800","1.87469","559.07159","50.64054","0.07381"
"225.21600","1.87675","555.39233","50.30728","0.07389"
"225.50400","1.87950","556.90363","50.44417","0.07400"
"225.79200","1.88187","555.80481","50.34464","0.07409"
"226.08000","1.88412","553.64056","50.14860","0.07418"
"226.36800","1.88662","552.27875","50.02525","0.07428"
"226.65600","1.88875","548.77728","49.70809","0.07436"
"226.94400","1.89150","549.59125","49.78181","0.07447"
"227.23200","1.89387","548.59247","49.69135","0.07456"
"227.52000","1.89606","546.85669","49.53412","0.07465"
"227.80800","1.89869","545.38611","49.40092","0.07475"
"228.09600","1.90075","541.96307","49.09086","0.07483"
"228.38400","1.90344","542.19049","49.11146","0.07494"
"228.67200","1.90587","541.85876","49.08141","0.07503"
"228.96000","1.90812","540.05945","48.91843","0.07512"
"229.24800","1.91069","538.61932","48.78798","0.07522"
"229.53600","1.91275","534.91296","48.45226","0.07531"
"229.82400","1.91537","535.08466","48.46781","0.07541"
"230.11200","1.91787","534.36047","48.40222","0.07551"
"230.40000","1.92019","533.64056","48.33701","0.07560"
"230.68800","1.92269","531.53229","48.14604","0.07570"
"230.97600","1.92475","528.19904","47.84412","0.07578"
"231.26400","1.92737","527.43341","47.77477","0.07588"
"231.55200","1.92981","526.71283","47.70950","0.07598"
"231.84000","1.93219","526.27374","47.66972","0.07607"
"232.12800","1.93469","523.86621","47.45165","0.07617"
"232.41600","1.93675","521.04181","47.19582","0.07625"
"232.70400","1.93937","519.91162","47.09344","0.07635"
"232.99200","1.94175","519.12201","47.02192","0.07645"
"233.28000","1.94425","519.06213","47.01650","0.07655"
"233.56800","1.94675","517.14709","46.84303","0.07664"
"233.85600","1.94875","513.75140","46.53545","0.07672"
"234.14400","1.95137","512.55457","46.42704","0.07683"
"234.43200","1.95375","511.48157","46.32985","0.07692"
"234.72000","1.95625","511.45157","46.32713","0.07702"
"235.00800","1.95875","509.54330","46.15429","0.07712"
"235.29600","1.96075","506.20377","45.85179","0.07719"
"235.58400","1.96337","504.86737","45.73074","0.07730"
"235.87200","1.96569","502.91641","45.55402","0.07739"
"236.16000","1.96831","504.13870","45.66474","0.07749"
"236.44800","1.97075","501.68292","45.44230","0.07759"
"236.73600","1.97281","498.59705","45.16278","0.07767"
"237.02400","1.97537","496.79434","44.99949","0.07777"
"237.31200","1.97769","495.27948","44.86227","0.07786"
"237.60000","1.98025","496.25793","44.95090","0.07796"
"237.88800","1.98275","493.67798","44.71721","0.07806"
"238.17600","1.98481","490.73160","44.45033","0.07814"
"238.46400","1.98737","489.11041","44.30348","0.07824"
"238.75200","1.98969","487.25949","44.13582","0.07833"
"239.04000","1.99225","487.92935","44.19650","0.07844"
"239.32800","1.99469","485.66983","43.99183","0.07853"
"239.61600","1.99681","482.58347","43.71227","0.07861"
"239.90400","1.99937","480.83557","43.55395","0.07872"
"240.19200","2.00162","478.82782","43.37209","0.07880"
"240.48000","2.00425","479.87552","43.46698","0.07891"
"240.76800","2.00669","477.24280","43.22852","0.07900"
"241.05600","2.00894","475.14172","43.03820","0.07909"
"241.34400","2.01131","472.40839","42.79062","0.07919"
"241.63200","2.01362","470.72983","42.63857","0.07928"
"241.92000","2.01625","471.10025","42.67212","0.07938"
"242.20800","2.01869","468.64902","42.45009","0.07948"
"242.49600","2.02094","466.72177","42.27552","0.07956"
"242.78400","2.02337","464.09079","42.03721","0.07966"
"243.07200","2.02562","461.75500","41.82563","0.07975"
"243.36000","2.02825","462.22015","41.86777","0.07985"
"243.64800","2.03069","460.06525","41.67258","0.07995"
"243.93600","2.03300","457.98569","41.48421","0.08004"
"244.22400","2.03537","455.48218","41.25744","0.08013"
"244.51200","2.03756","452.71628","41.00691","0.08022"
"244.80000","2.04025","453.11429","41.04296","0.08032"
"245.08800","2.04262","450.44180","40.80089","0.08042"
"245.37600","2.04506","449.96039","40.75728","0.08051"
"245.66400","2.04731","446.41644","40.43627","0.08060"
"245.95200","2.04956","443.91138","40.20937","0.08069"
"246.24000","2.05225","444.02805","40.21993","0.08080"
"246.52800","2.05462","440.84546","39.93166","0.08089"
"246.81600","2.05706","441.11124","39.95573","0.08099"
"247.10400","2.05931","436.86206","39.57084","0.08108"
"247.39200","2.06156","434.70975","39.37588","0.08116"
"247.68000","2.06419","434.36508","39.34466","0.08127"
"247.96800","2.06656","431.54092","39.08885","0.08136"
"248.25600","2.06912","432.14191","39.14329","0.08146"
"248.54400","2.07137","427.98935","38.76715","0.08155"
"248.83200","2.07356","425.05023","38.50093","0.08164"
"249.12000","2.07619","425.02148","38.49832","0.08174"
"249.40800","2.07856","421.70840","38.19823","0.08183"
"249.69600","2.08119","422.66748","38.28510","0.08194"
"249.98400","2.08331","418.16992","37.87771","0.08202"
"250.27200","2.08556","415.27072","37.61510","0.08211"
"250.56000","2.08825","414.76126","37.56895","0.08221"
"250.84800","2.09050","411.54126","37.27729","0.08230"
"251.13600","2.09325","412.98935","37.40845","0.08241"
"251.42400","2.09544","408.02960","36.95920","0.08250"
"251.71200","2.09756","405.21451","36.70421","0.08258"
"252.00000","2.10019","404.28214","36.61976","0.08268"
"252.28800","2.10250","400.87076","36.31076","0.08278"
"252.57600","2.10525","402.37936","36.44741","0.08288"
"252.86400","2.10744","398.05975","36.05614","0.08297"
"253.15200","2.10956","394.63141","35.74560","0.08305"
"253.44000","2.11219","393.64053","35.65585","0.08316"
"253.72800","2.11444","390.05029","35.33064","0.08325"
"254.01600","2.11725","391.36472","35.44970","0.08336"
"254.30400","2.11944","387.16708","35.06948","0.08344"
"254.59200","2.12150","383.35522","34.72421","0.08352"
"254.88000","2.12425","382.54807","34.65109","0.08363"
"255.16800","2.12644","378.42114","34.27728","0.08372"
"255.45600","2.12919","379.79169","34.40142","0.08383"
"255.74400","2.13150","375.93207","34.05182","0.08392"
"256.03200","2.13362","372.24664","33.71799","0.08400"
"256.32000","2.13625","370.04681","33.51873","0.08410"
"256.60800","2.13844","365.86890","33.14030","0.08419"
"256.89600","2.14119","366.62177","33.20849","0.08430"
"257.18400","2.14350","362.57556","32.84199","0.08439"
"257.47200","2.14556","358.01263","32.42868","0.08447"
"257.76000","2.14825","354.70648","32.12921","0.08458"
"258.04800","2.15044","349.02744","31.61480","0.08466"
"258.33600","2.15319","347.23938","31.45284","0.08477"
"258.62400","2.15550","341.93680","30.97254","0.08486"
"258.91200","2.15762","335.21725","30.36388","0.08495"
"259.20000","2.16025","328.45963","29.75178","0.08505"
"259.48800","2.16237","318.47708","28.84756","0.08513"
"259.77600","2.16512","310.65244","28.13881","0.08524"
"260.06400","2.16750","299.77936","27.15393","0.08533"
"260.35200","2.16962","288.39249","26.12251","0.08542"
"260.64000","2.17219","275.43896","24.94918","0.08552"
"260.92800","2.17437","261.32684","23.67091","0.08561"
"261.21600","2.17712","249.16539","22.56933","0.08571"
"261.50400","2.17950","238.06221","21.56361","0.08581"
"261.79200","2.18169","229.33980","20.77353","0.08589"
"262.08000","2.18419","220.15195","19.94130","0.08599"
"262.36800","2.18637","211.46922","19.15482","0.08608"
"262.65600","2.18906","204.56589","18.52952","0.08618"
"262.94400","2.19144","198.91681","18.01783","0.08628"
"263.23200","2.19375","192.12341","17.40248","0.08637"
"263.28800","2.19431","191.42674","17.33938","0.08639"