File: 20 per.is_metal_RawData/Specimen_RawData_1.csv
Time,Extension,Load,Tensile stress,Tensile strain (Extension)
(s),(mm),(N),(MPa),(mm/mm)
"0.00000","0.00000","-1.65356","-0.09018","0.00000"
"0.46400","0.00387","51.14428","2.78928","0.00015"
"0.92800","0.00775","113.05779","6.16589","0.00031"
"1.39200","0.01162","169.83641","9.26246","0.00046"
"1.85600","0.01537","221.22835","12.06525","0.00061"
"2.32000","0.01944","277.18793","15.11714","0.00077"
"2.78400","0.02325","325.49185","17.75152","0.00092"
"3.24800","0.02687","368.43372","20.09346","0.00106"
"3.71200","0.03112","418.12369","22.80343","0.00123"
"4.17600","0.03487","459.00931","25.03323","0.00137"
"4.64000","0.03844","495.91934","27.04621","0.00151"
"5.10400","0.04262","537.79443","29.32998","0.00168"
"5.56800","0.04644","574.83472","31.35006","0.00183"
"6.03200","0.05006","605.62415","33.02924","0.00197"
"6.49600","0.05412","641.49933","34.98578","0.00213"
"6.96000","0.05806","674.70551","36.79676","0.00229"
"7.42400","0.06169","701.11670","38.23717","0.00243"
"7.88800","0.06575","731.38220","39.88777","0.00259"
"8.35200","0.06962","758.98553","41.39319","0.00274"
"8.81600","0.07337","783.36035","42.72253","0.00289"
"9.28000","0.07731","807.85022","44.05815","0.00304"
"9.74400","0.08112","830.87878","45.31407","0.00319"
"10.20800","0.08506","853.51141","46.54840","0.00335"
"10.67200","0.08894","874.11591","47.67212","0.00350"
"11.13600","0.09269","892.47943","48.67361","0.00365"
"11.60000","0.09675","913.81232","49.83706","0.00381"
"12.06400","0.10056","930.91254","50.76966","0.00396"
"12.52800","0.10419","944.68408","51.52073","0.00410"
"12.99200","0.10844","964.59064","52.60638","0.00427"
"13.45600","0.11225","978.52209","53.36617","0.00442"
"13.92000","0.11581","988.75903","53.92447","0.00456"
"14.38400","0.12006","1005.92694","54.86076","0.00473"
"14.84800","0.12394","1019.00232","55.57386","0.00488"
"15.31200","0.12744","1025.84265","55.94691","0.00502"
"15.77600","0.13162","1039.38733","56.68561","0.00518"
"16.24000","0.13556","1051.45508","57.34375","0.00534"
"16.70400","0.13906","1056.79089","57.63475","0.00547"
"17.16800","0.14319","1067.47131","58.21724","0.00564"
"17.63200","0.14712","1077.85986","58.78381","0.00579"
"18.09600","0.15075","1082.76611","59.05138","0.00594"
"18.56000","0.15475","1091.02026","59.50154","0.00609"
"19.02400","0.15856","1097.83289","59.87309","0.00624"
"19.48800","0.16244","1104.28955","60.22522","0.00640"
"19.95200","0.16631","1109.81750","60.52670","0.00655"
"20.41600","0.17000","1114.10828","60.76070","0.00669"
"20.88000","0.17412","1121.60132","61.16935","0.00686"
"21.34400","0.17794","1126.34033","61.42781","0.00701"
"21.80800","0.18156","1128.38770","61.53947","0.00715"
"22.27200","0.18569","1135.20203","61.91110","0.00731"
"22.73600","0.18956","1140.46521","62.19814","0.00746"
"23.20000","0.19312","1139.85205","62.16470","0.00760"
"23.66400","0.19725","1145.95557","62.49757","0.00777"
"24.12800","0.20119","1151.45532","62.79752","0.00792"
"24.59200","0.20475","1150.09424","62.72329","0.00806"
"25.05600","0.20887","1155.73914","63.03115","0.00822"
"25.52000","0.21275","1159.78870","63.25200","0.00838"
"25.98400","0.21644","1159.00696","63.20937","0.00852"
"26.44800","0.22044","1162.46851","63.39815","0.00868"
"26.91200","0.22425","1166.23511","63.60357","0.00883"
"27.37600","0.22806","1166.44421","63.61497","0.00898"
"27.84000","0.23200","1168.92676","63.75037","0.00913"
"28.30400","0.23581","1171.59387","63.89582","0.00928"
"28.76800","0.23975","1173.13928","63.98011","0.00944"
"29.23200","0.24362","1174.63318","64.06158","0.00959"
"29.69600","0.24731","1175.24048","64.09470","0.00974"
"30.16000","0.25144","1178.99463","64.29945","0.00990"
"30.62400","0.25525","1179.56116","64.33034","0.01005"
"31.08800","0.25887","1178.94678","64.29684","0.01019"
"31.55200","0.26312","1183.54150","64.54742","0.01036"
"32.01600","0.26700","1185.06812","64.63068","0.01051"
"32.48000","0.27050","1182.27649","64.47843","0.01065"
"32.94400","0.27469","1186.28735","64.69717","0.01081"
"33.40800","0.27862","1189.08215","64.84959","0.01097"
"33.87200","0.28212","1184.96545","64.62508","0.01111"
"34.33600","0.28625","1188.74060","64.83096","0.01127"
"34.80000","0.29031","1191.90332","65.00345","0.01143"
"35.26400","0.29381","1187.87378","64.78369","0.01157"
"35.72800","0.29787","1190.68774","64.93716","0.01173"
"36.19200","0.30175","1192.25134","65.02243","0.01188"
"36.65600","0.30550","1190.64929","64.93506","0.01203"
"37.12000","0.30937","1191.65283","64.98979","0.01218"
"37.58400","0.31319","1191.95483","65.00626","0.01233"
"38.04800","0.31712","1192.92041","65.05892","0.01249"
"38.51200","0.32100","1193.65967","65.09924","0.01264"
"38.97600","0.32469","1192.32446","65.02642","0.01278"
"39.44000","0.32881","1195.14526","65.18026","0.01295"
"39.90400","0.33262","1194.78149","65.16042","0.01310"
"40.36800","0.33619","1192.06848","65.01246","0.01324"
"40.83200","0.34037","1195.17334","65.18179","0.01340"
"41.29600","0.34425","1196.06494","65.23042","0.01355"
"41.76000","0.34781","1192.41833","65.03154","0.01369"
"42.22400","0.35194","1195.29456","65.18840","0.01386"
"42.68800","0.35581","1196.93591","65.27792","0.01401"
"43.15200","0.35944","1193.01062","65.06384","0.01415"
"43.61600","0.36344","1194.56494","65.14861","0.01431"
"44.08000","0.36744","1197.01892","65.28244","0.01447"
"44.54400","0.37106","1193.54553","65.09302","0.01461"
"45.00800","0.37506","1194.62598","65.15194","0.01477"
"45.47200","0.37894","1196.17053","65.23618","0.01492"
"45.93600","0.38275","1194.76733","65.15965","0.01507"
"46.40000","0.38669","1195.21497","65.18406","0.01522"
"46.86400","0.39044","1195.02026","65.17344","0.01537"
"47.32800","0.39444","1195.65112","65.20785","0.01553"
"47.79200","0.39831","1194.98169","65.17134","0.01568"
"48.25600","0.40194","1193.94568","65.11484","0.01582"
"48.72000","0.40612","1196.34546","65.24571","0.01599"
"49.18400","0.40994","1196.09741","65.23219","0.01614"
"49.64800","0.41356","1193.51038","65.09109","0.01628"
"50.11200","0.41775","1196.45850","65.25188","0.01645"
"50.57600","0.42162","1197.53418","65.31055","0.01660"
"51.04000","0.42512","1193.07019","65.06709","0.01674"
"51.50400","0.42937","1196.48804","65.25349","0.01690"
"51.96800","0.43331","1197.70483","65.31985","0.01706"
"52.43200","0.43681","1193.56958","65.09432","0.01720"
"52.89600","0.44094","1195.01880","65.17336","0.01736"
"53.36000","0.44487","1197.26990","65.29613","0.01751"
"53.82400","0.44850","1193.73914","65.10357","0.01766"
"54.28800","0.45244","1194.42944","65.14122","0.01781"
"54.75200","0.45637","1195.10388","65.17800","0.01797"
"55.21600","0.46012","1193.23767","65.07623","0.01812"
"55.68000","0.46406","1194.38184","65.13863","0.01827"
"56.14400","0.46787","1193.27856","65.07845","0.01842"
"56.60800","0.47181","1193.84314","65.10925","0.01858"
"57.07200","0.47569","1194.04163","65.12007","0.01873"
"57.53600","0.47925","1190.87268","64.94724","0.01887"
"58.00000","0.48344","1193.44055","65.08729","0.01903"
"58.46400","0.48725","1193.27173","65.07808","0.01918"
"58.92800","0.49087","1189.95508","64.89720","0.01933"
"59.39200","0.49506","1192.34546","65.02757","0.01949"
"59.85600","0.49887","1193.64575","65.09848","0.01964"
"60.32000","0.50250","1188.98706","64.84441","0.01978"
"60.78400","0.50656","1190.65637","64.93545","0.01994"
"61.24800","0.51050","1192.93835","65.05990","0.02010"
"61.71200","0.51406","1188.34656","64.80947","0.02024"
"62.17600","0.51812","1189.83752","64.89079","0.02040"
"62.64000","0.52206","1191.61145","64.98753","0.02055"
"63.10400","0.52581","1188.42395","64.81370","0.02070"
"63.56800","0.52969","1188.47192","64.81631","0.02085"
"64.03200","0.53356","1189.67371","64.88185","0.02101"
"64.49600","0.53744","1188.75085","64.83153","0.02116"
"64.96000","0.54131","1187.69580","64.77399","0.02131"
"65.42400","0.54500","1187.20801","64.74738","0.02146"
"65.88800","0.54912","1188.48328","64.81693","0.02162"
"66.35200","0.55300","1187.99646","64.79038","0.02177"
"66.81600","0.55662","1186.10901","64.68745","0.02191"
"67.28000","0.56081","1188.73022","64.83040","0.02208"
"67.74400","0.56469","1188.11646","64.79693","0.02223"
"68.20800","0.56819","1184.62622","64.60658","0.02237"
"68.67200","0.57244","1187.74170","64.77649","0.02254"
"69.13600","0.57631","1188.95764","64.84280","0.02269"
"69.60000","0.57981","1184.19531","64.58308","0.02283"
"70.06400","0.58406","1187.06860","64.73978","0.02299"
"70.52800","0.58800","1188.81580","64.83507","0.02315"
"70.99200","0.59150","1183.88062","64.56591","0.02329"
"71.45600","0.59556","1185.39734","64.64863","0.02345"
"71.92000","0.59956","1187.33667","64.75439","0.02360"
"72.38400","0.60319","1183.76123","64.55940","0.02375"
"72.84800","0.60706","1183.87878","64.56581","0.02390"
"73.31200","0.61106","1185.02075","64.62809","0.02406"
"73.77600","0.61487","1183.92896","64.56855","0.02421"
"74.24000","0.61875","1183.56384","64.54864","0.02436"
"74.70400","0.62244","1182.08337","64.46790","0.02451"
"75.16800","0.62650","1183.78247","64.56056","0.02467"
"75.63200","0.63031","1182.62036","64.49718","0.02482"
"76.09600","0.63400","1180.23547","64.36712","0.02496"
"76.56000","0.63819","1182.66125","64.49941","0.02513"
"77.02400","0.64200","1182.77612","64.50568","0.02528"
"77.48800","0.64556","1178.88123","64.29326","0.02542"
"77.95200","0.64969","1180.74121","64.39470","0.02558"
"78.41600","0.65356","1182.40295","64.48533","0.02573"
"78.88000","0.65712","1177.76746","64.23251","0.02587"
"79.34400","0.66125","1179.41663","64.32246","0.02603"
"79.80800","0.66519","1181.50232","64.43621","0.02619"
"80.27200","0.66881","1177.08655","64.19538","0.02633"
"80.73600","0.67287","1178.25684","64.25921","0.02649"
"81.20000","0.67669","1179.20593","64.31097","0.02664"
"81.66400","0.68050","1176.85400","64.18270","0.02679"
"82.12800","0.68437","1176.59741","64.16871","0.02694"
"82.59200","0.68819","1176.89929","64.18517","0.02709"
"83.05600","0.69219","1176.67981","64.17320","0.02725"
"83.52000","0.69600","1176.03174","64.13786","0.02740"
"83.98400","0.69975","1175.19080","64.09200","0.02755"
"84.44800","0.70387","1177.22314","64.20284","0.02771"
"84.91200","0.70769","1175.58618","64.11356","0.02786"
"85.37600","0.71125","1173.42310","63.99559","0.02800"
"85.84000","0.71550","1176.08020","64.14050","0.02817"
"86.30400","0.71931","1175.69067","64.11926","0.02832"
"86.76800","0.72287","1172.43420","63.94165","0.02846"
"87.23200","0.72719","1175.46252","64.10681","0.02863"
"87.69600","0.73100","1176.16614","64.14519","0.02878"
"88.16000","0.73450","1171.76880","63.90536","0.02892"
"88.62400","0.73869","1173.64124","64.00748","0.02908"
"89.08800","0.74269","1175.64258","64.11663","0.02924"
"89.55200","0.74619","1170.96594","63.86158","0.02938"
"90.01600","0.75025","1171.96326","63.91597","0.02954"
"90.48000","0.75425","1173.63220","64.00699","0.02969"
"90.94400","0.75787","1171.24194","63.87663","0.02984"
"91.40800","0.76181","1171.01453","63.86423","0.02999"
"91.87200","0.76562","1170.57422","63.84021","0.03014"
"92.33600","0.76956","1170.89612","63.85777","0.03030"
"92.80000","0.77337","1170.17859","63.81864","0.03045"
"93.26400","0.77706","1168.16931","63.70906","0.03059"
"93.72800","0.78119","1170.21021","63.82036","0.03076"
"94.19200","0.78500","1169.43103","63.77787","0.03091"
"94.65600","0.78862","1166.73120","63.63063","0.03105"
"95.12000","0.79275","1168.36487","63.71972","0.03121"
"95.58400","0.79662","1169.61218","63.78775","0.03136"
"96.04800","0.80019","1164.62573","63.51580","0.03150"
"96.51200","0.80431","1166.74084","63.63115","0.03167"
"96.97600","0.80825","1168.35156","63.71900","0.03182"
"97.44000","0.81181","1164.23828","63.49467","0.03196"
"97.90400","0.81587","1164.91260","63.53144","0.03212"
"98.36800","0.81981","1167.01270","63.64598","0.03228"
"98.83200","0.82350","1163.34729","63.44608","0.03242"
"99.29600","0.82744","1163.20642","63.43839","0.03258"
"99.76000","0.83131","1164.98682","63.53549","0.03273"
"100.22400","0.83519","1162.81775","63.41720","0.03288"
"100.68800","0.83900","1162.44995","63.39714","0.03303"
"101.15200","0.84287","1162.86389","63.41971","0.03318"
"101.61600","0.84687","1162.86865","63.41997","0.03334"
"102.08000","0.85069","1161.63733","63.35282","0.03349"
"102.54400","0.85431","1160.32043","63.28100","0.03363"
"103.00800","0.85856","1163.18176","63.43705","0.03380"
"103.47200","0.86231","1161.55322","63.34823","0.03395"
"103.93600","0.86594","1158.86353","63.20154","0.03409"
"104.40000","0.87019","1162.12207","63.37926","0.03426"
"104.86400","0.87400","1162.05164","63.37542","0.03441"
"105.32800","0.87756","1157.73962","63.14025","0.03455"
"105.79200","0.88181","1160.57019","63.29462","0.03472"
"106.25600","0.88569","1161.74915","63.35892","0.03487"
"106.72000","0.88919","1156.83252","63.09078","0.03501"
"107.18400","0.89331","1158.95203","63.20637","0.03517"
"107.64800","0.89731","1161.13904","63.32565","0.03533"
"108.11200","0.90087","1156.81677","63.08992","0.03547"
"108.57600","0.90487","1157.34424","63.11869","0.03562"
"109.04000","0.90881","1158.40466","63.17652","0.03578"
"109.50400","0.91256","1156.69690","63.08338","0.03593"
"109.96800","0.91644","1156.17041","63.05467","0.03608"
"110.43200","0.92019","1155.15833","62.99947","0.03623"
"110.89600","0.92425","1155.96277","63.04334","0.03639"
"111.36000","0.92806","1155.59656","63.02337","0.03654"
"111.82400","0.93175","1153.35291","62.90101","0.03668"
"112.28800","0.93581","1154.79651","62.97974","0.03684"
"112.75200","0.93969","1155.31995","63.00829","0.03700"
"113.21600","0.94325","1151.29700","62.78888","0.03714"
"113.68000","0.94737","1152.88940","62.87573","0.03730"
"114.14400","0.95131","1154.56604","62.96717","0.03745"
"114.60800","0.95487","1149.95459","62.71567","0.03759"
"115.07200","0.95900","1152.14478","62.83512","0.03776"
"115.53600","0.96287","1153.09351","62.88686","0.03791"
"116.00000","0.96650","1149.26904","62.67828","0.03805"
"116.46400","0.97056","1150.09497","62.72333","0.03821"
"116.92800","0.97444","1151.52258","62.80119","0.03836"
"117.39200","0.97819","1148.41052","62.63146","0.03851"
"117.85600","0.98206","1148.58667","62.64107","0.03866"
"118.32000","0.98600","1149.69299","62.70140","0.03882"
"118.78400","0.98987","1147.86182","62.60154","0.03897"
"119.24800","0.99375","1147.66553","62.59083","0.03912"
"119.71200","0.99744","1147.25452","62.56842","0.03927"
"120.17600","1.00156","1148.06726","62.61274","0.03943"
"120.64000","1.00537","1146.84351","62.54600","0.03958"
"121.10400","1.00900","1145.25659","62.45945","0.03972"
"121.56800","1.01325","1147.59656","62.58707","0.03989"
"122.03200","1.01706","1147.22852","62.56700","0.04004"
"122.49600","1.02062","1143.66492","62.37265","0.04018"
"122.96000","1.02481","1146.55054","62.53002","0.04035"
"123.42400","1.02875","1147.35706","62.57401","0.04050"
"123.88800","1.03225","1142.32324","62.29948","0.04064"
"124.35200","1.03644","1145.37927","62.46614","0.04080"
"124.81600","1.04044","1147.44690","62.57891","0.04096"
"125.28000","1.04387","1141.80188","62.27104","0.04110"
"125.74400","1.04800","1143.62488","62.37046","0.04126"
"126.20800","1.05194","1145.29919","62.46178","0.04141"
"126.67200","1.05556","1141.67493","62.26412","0.04156"
"127.13600","1.05956","1142.23792","62.29482","0.04172"
"127.60000","1.06344","1142.15784","62.29045","0.04187"
"128.06400","1.06725","1141.10144","62.23284","0.04202"
"128.52800","1.07112","1140.97852","62.22614","0.04217"
"128.99200","1.07487","1139.80908","62.16236","0.04232"
"129.45600","1.07894","1140.76453","62.21447","0.04248"
"129.92000","1.08275","1140.28357","62.18824","0.04263"
"130.38400","1.08637","1137.51343","62.03716","0.04277"
"130.84800","1.09056","1139.41528","62.14088","0.04294"
"131.31200","1.09437","1139.20313","62.12931","0.04309"
"131.77600","1.09794","1135.29504","61.91618","0.04323"
"132.24000","1.10212","1137.36597","62.02912","0.04339"
"132.70400","1.10600","1138.67578","62.10056","0.04354"
"133.16800","1.10956","1134.22522","61.85783","0.04368"
"133.63200","1.11362","1135.06152","61.90344","0.04384"
"134.09600","1.11756","1137.56018","62.03971","0.04400"
"134.56000","1.12119","1133.06604","61.79461","0.04414"
"135.02400","1.12519","1133.65808","61.82690","0.04430"
"135.48800","1.12912","1135.31433","61.91723","0.04445"
"135.95200","1.13287","1132.47083","61.76215","0.04460"
"136.41600","1.13681","1132.62183","61.77039","0.04476"
"136.88000","1.14062","1132.89514","61.78529","0.04491"
"137.34400","1.14456","1131.95044","61.73377","0.04506"
"137.80800","1.14837","1131.20557","61.69315","0.04521"
"138.27200","1.15212","1130.20032","61.63832","0.04536"
"138.73600","1.15625","1131.61462","61.71545","0.04552"
"139.20000","1.16006","1130.97705","61.68068","0.04567"
"139.66400","1.16369","1128.51489","61.54641","0.04581"
"140.12800","1.16787","1131.15979","61.69065","0.04598"
"140.59200","1.17175","1131.08191","61.68640","0.04613"
"141.05600","1.17525","1126.85559","61.45591","0.04627"
"141.52000","1.17950","1129.81531","61.61732","0.04644"
"141.98400","1.18337","1130.36804","61.64747","0.04659"
"142.44800","1.18694","1126.27832","61.42443","0.04673"
"142.91200","1.19112","1128.12866","61.52534","0.04689"
"143.37600","1.19506","1129.87573","61.62062","0.04705"
"143.84000","1.19862","1125.76453","61.39640","0.04719"
"144.30400","1.20262","1126.02747","61.41075","0.04735"
"144.76800","1.20656","1127.48657","61.49032","0.04750"
"145.23200","1.21025","1123.92468","61.29607","0.04765"
"145.69600","1.21419","1125.13245","61.36193","0.04780"
"146.16000","1.21806","1124.46631","61.32560","0.04796"
"146.62400","1.22194","1123.89343","61.29436","0.04811"
"147.08800","1.22581","1123.98108","61.29914","0.04826"
"147.55200","1.22944","1121.35986","61.15619","0.04840"
"148.01600","1.23356","1123.04175","61.24791","0.04857"
"148.48000","1.23737","1122.57788","61.22261","0.04872"
"148.94400","1.24100","1119.12549","61.03433","0.04886"
"149.40800","1.24519","1121.46899","61.16214","0.04902"
"149.87200","1.24900","1122.17786","61.20080","0.04917"
"150.33600","1.25262","1117.41492","60.94104","0.04932"
"150.80000","1.25669","1119.19006","61.03785","0.04948"
"151.26400","1.26062","1120.80029","61.12567","0.04963"
"151.72800","1.26419","1116.20203","60.87489","0.04977"
"152.19200","1.26825","1116.78564","60.90672","0.04993"
"152.65600","1.27219","1118.86450","61.02010","0.05009"
"153.12000","1.27587","1115.28674","60.82497","0.05023"
"153.58400","1.27987","1115.44971","60.83386","0.05039"
"154.04800","1.28375","1116.70740","60.90245","0.05054"
"154.51200","1.28756","1114.44031","60.77881","0.05069"
"154.97600","1.29144","1113.62988","60.73461","0.05084"
"155.44000","1.29519","1113.73218","60.74019","0.05099"
"155.90400","1.29925","1113.47656","60.72625","0.05115"
"156.36800","1.30306","1112.88733","60.69411","0.05130"
"156.83200","1.30681","1111.91394","60.64103","0.05145"
"157.29600","1.31094","1113.42395","60.72338","0.05161"
"157.76000","1.31475","1112.53906","60.67512","0.05176"
"158.22400","1.31831","1109.52979","60.51100","0.05190"
"158.68800","1.32256","1112.06226","60.64912","0.05207"
"159.15200","1.32644","1112.45471","60.67052","0.05222"
"159.61600","1.32994","1107.82324","60.41793","0.05236"
"160.08000","1.33419","1110.91504","60.58655","0.05253"
"160.54400","1.33812","1112.37256","60.66604","0.05268"
"161.00800","1.34162","1106.95898","60.37080","0.05282"
"161.47200","1.34569","1108.81348","60.47194","0.05298"
"161.93600","1.34969","1110.57690","60.56811","0.05314"
"162.40000","1.35325","1106.03662","60.32050","0.05328"
"162.86400","1.35719","1106.58130","60.35020","0.05343"
"163.32800","1.36119","1108.06140","60.43092","0.05359"
"163.79200","1.36494","1105.70203","60.30225","0.05374"
"164.25600","1.36887","1105.26135","60.27821","0.05389"
"164.72000","1.37262","1104.47485","60.23532","0.05404"
"165.18400","1.37662","1105.14343","60.27178","0.05420"
"165.64800","1.38044","1104.15588","60.21793","0.05435"
"166.11200","1.38412","1101.94312","60.09724","0.05449"
"166.57600","1.38825","1103.43628","60.17868","0.05466"
"167.04000","1.39206","1103.24524","60.16826","0.05481"
"167.50400","1.39569","1099.74011","59.97710","0.05495"
"167.96800","1.39981","1101.45056","60.07038","0.05511"
"168.43200","1.40369","1102.42969","60.12378","0.05526"
"168.89600","1.40725","1097.55481","59.85792","0.05540"
"169.36000","1.41137","1099.23401","59.94950","0.05557"
"169.82400","1.41537","1101.17310","60.05525","0.05572"
"170.28800","1.41894","1096.32373","59.79078","0.05586"
"170.75200","1.42300","1097.81848","59.87230","0.05602"
"171.21600","1.42687","1098.70300","59.92054","0.05618"
"171.68000","1.43056","1095.15295","59.72692","0.05632"
"172.14400","1.43450","1095.16553","59.72761","0.05648"
"172.60800","1.43837","1096.02527","59.77450","0.05663"
"173.07200","1.44225","1094.31262","59.68110","0.05678"
"173.53600","1.44612","1093.71338","59.64841","0.05693"
"174.00000","1.44987","1093.64172","59.64451","0.05708"
"174.46400","1.45400","1093.99329","59.66368","0.05724"
"174.92800","1.45775","1092.49243","59.58183","0.05739"
"175.39200","1.46144","1090.92920","59.49657","0.05754"
"175.85600","1.46562","1092.86304","59.60204","0.05770"
"176.32000","1.46944","1091.73474","59.54050","0.05785"
"176.78400","1.47300","1088.86853","59.38419","0.05799"
"177.24800","1.47731","1091.69080","59.53811","0.05816"
"177.71200","1.48112","1092.05884","59.55818","0.05831"
"178.17600","1.48462","1087.39758","59.30397","0.05845"
"178.64000","1.48881","1089.42688","59.41464","0.05861"
"179.10400","1.49281","1091.40894","59.52274","0.05877"
"179.56800","1.49625","1086.01965","59.22882","0.05891"
"180.03200","1.50037","1087.37683","59.30284","0.05907"
"180.49600","1.50437","1089.06860","59.39510","0.05923"
"180.96000","1.50800","1085.39587","59.19480","0.05937"
"181.42400","1.51194","1085.29529","59.18932","0.05953"
"181.88800","1.51581","1085.46045","59.19832","0.05968"
"182.35200","1.51962","1084.10974","59.12466","0.05983"
"182.81600","1.52350","1083.48291","59.09047","0.05998"
"183.28000","1.52731","1082.70789","59.04820","0.06013"
"183.74400","1.53131","1083.04382","59.06652","0.06029"
"184.20800","1.53512","1082.31116","59.02657","0.06044"
"184.67200","1.53875","1079.65015","58.88144","0.06058"
"185.13600","1.54287","1080.99548","58.95481","0.06074"
"185.60000","1.54675","1081.09033","58.95999","0.06090"
"186.06400","1.55031","1077.07336","58.74091","0.06104"
"186.52800","1.55450","1078.73401","58.83148","0.06120"
"186.99200","1.55837","1079.46448","58.87132","0.06135"
"187.45600","1.56194","1075.08850","58.63266","0.06149"
"187.92000","1.56606","1076.19739","58.69314","0.06166"
"188.38400","1.56994","1078.11304","58.79761","0.06181"
"188.84800","1.57356","1073.54712","58.54860","0.06195"
"189.31200","1.57756","1073.69360","58.55659","0.06211"
"189.77600","1.58150","1075.48401","58.65423","0.06226"
"190.24000","1.58525","1072.19727","58.47498","0.06241"
"190.70400","1.58919","1072.03625","58.46620","0.06257"
"191.16800","1.59306","1072.48059","58.49043","0.06272"
"191.63200","1.59694","1071.31372","58.42679","0.06287"
"192.09600","1.60081","1069.99170","58.35469","0.06302"
"192.56000","1.60450","1069.39294","58.32204","0.06317"
"193.02400","1.60862","1071.12183","58.41633","0.06333"
"193.48800","1.61244","1069.00928","58.30112","0.06348"
"193.95200","1.61606","1067.14075","58.19921","0.06362"
"194.41600","1.62031","1069.48877","58.32727","0.06379"
"194.88000","1.62412","1068.86792","58.29341","0.06394"
"195.34400","1.62769","1064.93481","58.07890","0.06408"
"195.80800","1.63194","1067.53833","58.22089","0.06425"
"196.27200","1.63581","1068.18420","58.25612","0.06440"
"196.73600","1.63931","1062.99805","57.97328","0.06454"
"197.20000","1.64344","1064.76196","58.06948","0.06470"
"197.66400","1.64744","1067.12622","58.19842","0.06486"
"198.12800","1.65094","1061.65039","57.89978","0.06500"
"198.59200","1.65500","1062.90002","57.96793","0.06516"
"199.05600","1.65894","1064.05054","58.03068","0.06531"
"199.52000","1.66262","1060.89087","57.85836","0.06546"
"199.98400","1.66656","1060.41064","57.83217","0.06561"
"200.44800","1.67037","1060.01270","57.81046","0.06576"
"200.91200","1.67431","1059.57837","57.78678","0.06592"
"201.37600","1.67819","1059.25256","57.76901","0.06607"
"201.84000","1.68194","1057.19128","57.65659","0.06622"
"202.30400","1.68600","1058.10486","57.70642","0.06638"
"202.76800","1.68981","1057.57495","57.67752","0.06653"
"203.23200","1.69337","1054.21021","57.49401","0.06667"
"203.69600","1.69756","1055.39294","57.55851","0.06683"
"204.16000","1.70144","1056.39551","57.61319","0.06699"
"204.62400","1.70500","1051.86218","57.36596","0.06713"
"205.08800","1.70919","1053.53845","57.45737","0.06729"
"205.55200","1.71300","1054.37036","57.50275","0.06744"
"206.01600","1.71662","1050.13074","57.27153","0.06758"
"206.48000","1.72062","1050.67261","57.30108","0.06774"
"206.94400","1.72456","1052.41809","57.39627","0.06790"
"207.40800","1.72831","1048.05859","57.15852","0.06804"
"207.87200","1.73219","1048.27954","57.17057","0.06820"
"208.33600","1.73619","1049.61316","57.24330","0.06835"
"208.80000","1.73994","1046.70239","57.08455","0.06850"
"209.26400","1.74387","1046.27759","57.06139","0.06866"
"209.72800","1.74762","1046.56970","57.07732","0.06880"
"210.19200","1.75162","1045.87061","57.03919","0.06896"
"210.65600","1.75550","1044.42065","56.96011","0.06911"
"211.12000","1.75912","1043.20142","56.89362","0.06926"
"211.58400","1.76331","1044.57739","56.96866","0.06942"
"212.04800","1.76719","1043.87183","56.93018","0.06957"
"212.51200","1.77075","1041.14673","56.78156","0.06971"
"212.97600","1.77500","1043.09363","56.88774","0.06988"
"213.44000","1.77887","1042.81079","56.87231","0.07003"
"213.90400","1.78231","1038.40674","56.63213","0.07017"
"214.36800","1.78656","1040.89990","56.76810","0.07034"
"214.83200","1.79056","1042.20056","56.83904","0.07049"
"215.29600","1.79400","1036.83032","56.54615","0.07063"
"215.76000","1.79819","1038.57471","56.64129","0.07079"
"216.22400","1.80212","1040.33240","56.73715","0.07095"
"216.68800","1.80569","1035.49976","56.47359","0.07109"
"217.15200","1.80969","1036.22791","56.51330","0.07125"
"217.61600","1.81362","1036.44958","56.52539","0.07140"
"218.08000","1.81731","1033.53784","56.36659","0.07155"
"218.54400","1.82131","1033.89294","56.38596","0.07171"
"219.00800","1.82506","1032.89001","56.33126","0.07185"
"219.47200","1.82906","1032.87915","56.33067","0.07201"
"219.93600","1.83287","1031.98547","56.28193","0.07216"
"220.40000","1.83656","1029.21777","56.13099","0.07231"
"220.86400","1.84069","1030.86694","56.22093","0.07247"
"221.32800","1.84450","1029.86633","56.16636","0.07262"
"221.79200","1.84806","1026.50146","55.98285","0.07276"
"222.25600","1.85225","1028.31494","56.08175","0.07292"
"222.72000","1.85612","1028.48206","56.09086","0.07308"
"223.18400","1.85969","1023.73969","55.83223","0.07322"
"223.64800","1.86375","1024.87195","55.89397","0.07338"
"224.11200","1.86775","1026.64294","55.99056","0.07353"
"224.57600","1.87125","1021.17883","55.69256","0.07367"
"225.04000","1.87531","1021.85394","55.72938","0.07383"
"225.50400","1.87931","1023.76605","55.83366","0.07399"
"225.96800","1.88300","1019.82916","55.61895","0.07413"
"226.43200","1.88700","1019.87488","55.62145","0.07429"
"226.89600","1.89081","1020.64691","55.66355","0.07444"
"227.36000","1.89462","1018.10156","55.52473","0.07459"
"227.82400","1.89850","1017.40063","55.48651","0.07474"
"228.28800","1.90231","1016.99615","55.46445","0.07489"
"228.75200","1.90631","1016.73602","55.45026","0.07505"
"229.21600","1.91019","1015.67310","55.39229","0.07520"
"229.68000","1.91381","1013.70563","55.28499","0.07535"
"230.14400","1.91800","1015.31836","55.37295","0.07551"
"230.60800","1.92187","1014.57910","55.33263","0.07566"
"231.07200","1.92537","1010.82538","55.12791","0.07580"
"231.53600","1.92969","1013.40759","55.26874","0.07597"
"232.00000","1.93350","1012.90277","55.24121","0.07612"
"232.46400","1.93700","1008.82184","55.01864","0.07626"
"232.92800","1.94125","1010.32928","55.10085","0.07643"
"233.39200","1.94519","1011.71472","55.17641","0.07658"
"233.85600","1.94869","1007.28979","54.93509","0.07672"
"234.32000","1.95281","1007.70740","54.95786","0.07688"
"234.78400","1.95675","1009.06250","55.03176","0.07704"
"235.24800","1.96037","1004.58917","54.78780","0.07718"
"235.71200","1.96437","1004.93829","54.80684","0.07734"
"236.17600","1.96825","1005.48120","54.83645","0.07749"
"236.64000","1.97200","1003.35712","54.72061","0.07764"
"237.10400","1.97594","1003.25842","54.71523","0.07779"
"237.56800","1.97962","1000.73169","54.57743","0.07794"
"238.03200","1.98369","1001.86578","54.63927","0.07810"
"238.49600","1.98750","1000.56335","54.56824","0.07825"
"238.96000","1.99112","997.40271","54.39587","0.07839"
"239.42400","1.99531","998.92310","54.47879","0.07856"
"239.88800","1.99912","998.51154","54.45634","0.07871"
"240.35200","2.00275","994.60065","54.24305","0.07885"
"240.81600","2.00687","995.35919","54.28442","0.07901"
"241.28000","2.01075","996.79187","54.36256","0.07916"
"241.74400","2.01431","991.39911","54.06845","0.07930"
"242.20800","2.01844","992.36407","54.12107","0.07947"
"242.67200","2.02231","993.57245","54.18698","0.07962"
"243.13600","2.02594","989.42175","53.96061","0.07976"
"243.60000","2.03000","989.29926","53.95393","0.07992"
"244.06400","2.03387","990.89240","54.04081","0.08007"
"244.52800","2.03762","987.51886","53.85683","0.08022"
"244.99200","2.04162","986.77997","53.81653","0.08038"
"245.45600","2.04537","986.90527","53.82337","0.08053"
"245.92000","2.04931","985.10754","53.72532","0.08068"
"246.38400","2.05319","984.12177","53.67156","0.08083"
"246.84800","2.05694","983.71710","53.64949","0.08098"
"247.31200","2.06100","983.58325","53.64219","0.08114"
"247.77600","2.06487","982.33887","53.57433","0.08129"
"248.24000","2.06844","979.82318","53.43713","0.08143"
"248.70400","2.07269","981.57178","53.53249","0.08160"
"249.16800","2.07650","980.81238","53.49107","0.08175"
"249.63200","2.08006","976.91010","53.27826","0.08189"
"250.09600","2.08431","979.16992","53.40150","0.08206"
"250.56000","2.08819","979.70013","53.43042","0.08221"
"251.02400","2.09175","974.65570","53.15530","0.08235"
"251.48800","2.09587","976.21588","53.24039","0.08251"
"251.95200","2.09987","977.86877","53.33054","0.08267"
"252.41600","2.10337","972.05713","53.01358","0.08281"
"252.88000","2.10737","972.37073","53.03069","0.08297"
"253.34400","2.11144","974.39459","53.14106","0.08313"
"253.80800","2.11506","970.54730","52.93124","0.08327"
"254.27200","2.11900","969.88165","52.89494","0.08343"
"254.73600","2.12281","969.81696","52.89141","0.08358"
"255.20000","2.12675","968.75958","52.83374","0.08373"
"255.66400","2.13056","967.27386","52.75272","0.08388"
"256.12800","2.13431","965.48553","52.65519","0.08403"
"256.59200","2.13837","966.09534","52.68845","0.08419"
"257.05600","2.14219","965.03784","52.63077","0.08434"
"257.52000","2.14587","962.00378","52.46530","0.08448"
"257.98400","2.15000","963.30121","52.53606","0.08465"
"258.44800","2.15387","963.14734","52.52767","0.08480"
"258.91200","2.15737","958.35657","52.26639","0.08494"
"259.37600","2.16156","959.68347","52.33876","0.08510"
"259.84000","2.16550","960.58899","52.38814","0.08526"
"260.30400","2.16900","955.38354","52.10425","0.08539"
"260.76800","2.17312","956.43683","52.16169","0.08556"
"261.23200","2.17700","957.38837","52.21359","0.08571"
"261.69600","2.18069","952.92712","51.97028","0.08585"
"262.16000","2.18469","952.52692","51.94846","0.08601"
"262.62400","2.18856","953.46057","51.99937","0.08616"
"263.08800","2.19237","950.20142","51.82163","0.08631"
"263.55200","2.19631","949.67719","51.79304","0.08647"
"264.01600","2.20006","949.60986","51.78937","0.08662"
"264.48000","2.20406","948.49933","51.72880","0.08677"
"264.94400","2.20787","946.90265","51.64172","0.08692"
"265.40800","2.21156","945.60577","51.57100","0.08707"
"265.87200","2.21575","946.33820","51.61094","0.08723"
"266.33600","2.21956","944.28595","51.49902","0.08738"
"266.80000","2.22312","941.78479","51.36261","0.08752"
"267.26400","2.22744","943.30676","51.44561","0.08769"
"267.72800","2.23125","942.88336","51.42252","0.08784"
"268.19200","2.23475","938.88110","51.20425","0.08798"
"268.65600","2.23900","940.63794","51.30006","0.08815"
"269.12000","2.24294","941.36621","51.33978","0.08830"
"269.58400","2.24637","935.68665","51.03003","0.08844"
"270.04800","2.25056","936.75525","51.08831","0.08860"
"270.51200","2.25450","938.12982","51.16327","0.08876"
"270.97600","2.25806","933.30762","50.90028","0.08890"
"271.44000","2.26212","933.39209","50.90489","0.08906"
"271.90400","2.26606","933.98383","50.93716","0.08922"
"272.36800","2.26975","930.39771","50.74158","0.08936"
"272.83200","2.27369","929.94867","50.71709","0.08952"
"273.29600","2.27750","929.26202","50.67965","0.08967"
"273.76000","2.28144","928.25348","50.62464","0.08982"
"274.22400","2.28525","927.10052","50.56176","0.08997"
"274.68800","2.28894","924.44702","50.41705","0.09012"
"275.15200","2.29306","925.27869","50.46241","0.09028"
"275.61600","2.29687","924.22571","50.40498","0.09043"
"276.08000","2.30044","920.18945","50.18485","0.09057"
"276.54400","2.30462","921.75732","50.27036","0.09073"
"277.00800","2.30850","921.28131","50.24440","0.09089"
"277.47200","2.31206","916.72754","49.99605","0.09103"
"277.93600","2.31619","917.54858","50.04082","0.09119"
"278.40000","2.32012","918.41498","50.08808","0.09134"
"278.86400","2.32369","913.12201","49.79941","0.09148"
"279.32800","2.32775","913.52258","49.82125","0.09164"
"279.79200","2.33162","914.58820","49.87937","0.09180"
"280.25600","2.33531","910.03406","49.63100","0.09194"
"280.72000","2.33925","909.48328","49.60096","0.09210"
"281.18400","2.34319","910.13721","49.63663","0.09225"
"281.64800","2.34700","907.32941","49.48350","0.09240"
"282.11200","2.35094","906.10760","49.41686","0.09256"
"282.57600","2.35469","905.65643","49.39226","0.09270"
"283.04000","2.35875","905.20734","49.36776","0.09286"
"283.50400","2.36256","902.79767","49.23635","0.09301"
"283.96800","2.36619","901.05188","49.14114","0.09316"
"284.43200","2.37044","902.09851","49.19822","0.09332"
"284.89600","2.37419","900.81122","49.12801","0.09347"
"285.36000","2.37781","896.90265","48.91485","0.09361"
"285.82400","2.38206","899.07635","49.03339","0.09378"
"286.28800","2.38594","898.39606","48.99629","0.09393"
"286.75200","2.38937","893.44440","48.72624","0.09407"
"287.21600","2.39362","894.89752","48.80549","0.09424"
"287.68000","2.39756","895.80695","48.85509","0.09439"
"288.14400","2.40106","890.13531","48.54577","0.09453"
"288.60800","2.40519","890.72369","48.57786","0.09469"
"289.07200","2.40912","891.87537","48.64067","0.09485"
"289.53600","2.41275","887.32605","48.39256","0.09499"
"290.00000","2.41669","886.51135","48.34813","0.09515"
"290.46400","2.42056","886.54199","48.34980","0.09530"
"290.92800","2.42444","884.30121","48.22760","0.09545"
"291.39200","2.42831","883.29541","48.17274","0.09560"
"291.85600","2.43206","881.51709","48.07576","0.09575"
"292.32000","2.43606","881.21277","48.05916","0.09591"
"292.78400","2.43994","879.67169","47.97511","0.09606"
"293.24800","2.44356","876.37695","47.79543","0.09620"
"293.71200","2.44769","877.03448","47.83129","0.09637"
"294.17600","2.45156","876.37280","47.79520","0.09652"
"294.64000","2.45512","872.39954","47.57851","0.09666"
"295.10400","2.45931","873.14264","47.61903","0.09682"
"295.56800","2.46312","872.91608","47.60668","0.09697"
"296.03200","2.46675","868.00409","47.33879","0.09712"
"296.49600","2.47081","868.56036","47.36913","0.09728"
"296.96000","2.47469","869.35748","47.41260","0.09743"
"297.42400","2.47837","864.27936","47.13565","0.09757"
"297.88800","2.48231","863.72180","47.10524","0.09773"
"298.35200","2.48631","865.22717","47.18734","0.09789"
"298.81600","2.49006","860.74182","46.94273","0.09803"
"299.28000","2.49400","859.76727","46.88958","0.09819"
"299.74400","2.49781","860.10675","46.90809","0.09834"
"300.20800","2.50175","857.76233","46.78023","0.09849"
"300.67200","2.50562","855.84271","46.67554","0.09865"
"301.13600","2.50931","854.45996","46.60013","0.09879"
"301.60000","2.51344","854.26263","46.58937","0.09895"
"302.06400","2.51725","852.25598","46.47993","0.09910"
"302.52800","2.52087","849.98627","46.35614","0.09925"
"302.99200","2.52506","850.86633","46.40414","0.09941"
"303.45600","2.52894","849.03937","46.30450","0.09956"
"303.92000","2.53244","845.22839","46.09666","0.09970"
"304.38400","2.53675","847.12787","46.20025","0.09987"
"304.84800","2.54062","846.55408","46.16896","0.10002"
"305.31200","2.54412","841.29144","45.88195","0.10016"
"305.77600","2.54831","842.73724","45.96080","0.10033"
"306.24000","2.55225","843.50098","46.00245","0.10048"
"306.70400","2.55581","837.23303","45.66061","0.10062"
"307.16800","2.55981","837.78949","45.69096","0.10078"
"307.63200","2.56381","838.21033","45.71391","0.10094"
"308.09600","2.56744","833.53210","45.45877","0.10108"
"308.56000","2.57144","833.23169","45.44239","0.10124"
"309.02400","2.57531","832.53131","45.40419","0.10139"
"309.48800","2.57919","830.45972","45.29121","0.10154"
"309.95200","2.58300","828.62115","45.19094","0.10169"
"310.41600","2.58675","826.84869","45.09428","0.10184"
"310.88000","2.59081","826.69055","45.08565","0.10200"
"311.34400","2.59462","824.65875","44.97484","0.10215"
"311.80800","2.59819","821.04187","44.77759","0.10229"
"312.27200","2.60244","821.95782","44.82754","0.10246"
"312.73600","2.60625","820.94849","44.77250","0.10261"
"313.20000","2.60981","815.86993","44.49552","0.10275"
"313.66400","2.61394","816.25378","44.51646","0.10291"
"314.12800","2.61787","816.83966","44.54841","0.10307"
"314.59200","2.62137","811.01221","44.23059","0.10320"
"315.05600","2.62550","810.96155","44.22783","0.10337"
"315.52000","2.62944","812.06812","44.28818","0.10352"
"315.98400","2.63306","806.66949","43.99376","0.10366"
"316.44800","2.63712","806.22089","43.96929","0.10382"
"316.91200","2.64100","806.90955","44.00685","0.10398"
"317.37600","2.64475","802.67834","43.77608","0.10412"
"317.84000","2.64862","800.96814","43.68282","0.10428"
"318.30400","2.65244","800.76575","43.67178","0.10443"
"318.76800","2.65644","798.45282","43.54564","0.10458"
"319.23200","2.66031","796.60632","43.44493","0.10474"
"319.69600","2.66400","794.68817","43.34032","0.10488"
"320.16000","2.66812","794.52374","43.33136","0.10504"
"320.62400","2.67194","792.45483","43.21852","0.10519"
"321.08800","2.67550","789.09692","43.03539","0.10533"
"321.55200","2.67981","790.50940","43.11242","0.10550"
"322.01600","2.68356","788.47174","43.00129","0.10565"
"322.48000","2.68712","784.25311","42.77122","0.10579"
"322.94400","2.69137","785.25867","42.82606","0.10596"
"323.40800","2.69531","785.32397","42.82962","0.10611"
"323.87200","2.69881","779.63165","42.51918","0.10625"
"324.33600","2.70294","779.62579","42.51886","0.10641"
"324.80000","2.70694","780.32867","42.55719","0.10657"
"325.26400","2.71044","774.79437","42.25536","0.10671"
"325.72800","2.71450","774.16284","42.22092","0.10687"
"326.19200","2.71844","774.41840","42.23486","0.10703"
"326.65600","2.72212","770.17145","42.00324","0.10717"
"327.12000","2.72612","769.12775","41.94632","0.10733"
"327.58400","2.72981","767.06714","41.83394","0.10747"
"328.04800","2.73381","766.12280","41.78244","0.10763"
"328.51200","2.73762","763.68585","41.64953","0.10778"
"328.97600","2.74131","760.71045","41.48726","0.10793"
"329.44000","2.74544","760.46875","41.47408","0.10809"
"329.90400","2.74925","758.70923","41.37812","0.10824"
"330.36800","2.75287","754.70441","41.15971","0.10838"
"330.83200","2.75700","754.87311","41.16891","0.10854"
"331.29600","2.76094","754.13696","41.12876","0.10870"
"331.76000","2.76444","748.64600","40.82930","0.10884"
"332.22400","2.76856","748.64343","40.82915","0.10900"
"332.68800","2.77250","748.60577","40.82710","0.10915"
"333.15200","2.77606","743.11591","40.52770","0.10929"
"333.61600","2.78019","742.67371","40.50358","0.10946"
"334.08000","2.78406","743.07050","40.52522","0.10961"
"334.54400","2.78775","738.33795","40.26712","0.10975"
"335.00800","2.79169","736.68097","40.17675","0.10991"
"335.47200","2.79556","736.64850","40.17498","0.11006"
"335.93600","2.79944","733.04272","39.97833","0.11021"
"336.40000","2.80331","730.89081","39.86097","0.11037"
"336.86400","2.80712","730.21521","39.82413","0.11052"
"337.32800","2.81112","728.04950","39.70601","0.11067"
"337.79200","2.81500","725.58813","39.57178","0.11083"
"338.25600","2.81862","723.11346","39.43682","0.11097"
"338.72000","2.82281","723.01428","39.43141","0.11113"
"339.18400","2.82662","720.42023","39.28993","0.11128"
"339.64800","2.83019","716.99915","39.10336","0.11142"
"340.11200","2.83444","717.74658","39.14412","0.11159"
"340.57600","2.83831","716.31403","39.06599","0.11174"
"341.04000","2.84181","710.98425","38.77532","0.11188"
"341.50400","2.84606","711.66418","38.81240","0.11205"
"341.96800","2.85000","711.73462","38.81624","0.11220"
"342.43200","2.85344","705.16199","38.45779","0.11234"
"342.89600","2.85750","704.59985","38.42713","0.11250"
"343.36000","2.86156","705.15942","38.45765","0.11266"
"343.82400","2.86512","699.84894","38.16803","0.11280"
"344.28800","2.86912","698.25250","38.08096","0.11296"
"344.75200","2.87306","698.12073","38.07377","0.11311"
"345.21600","2.87687","694.73932","37.88936","0.11326"
"345.68000","2.88069","692.42780","37.76329","0.11341"
"346.14400","2.88450","690.32062","37.64838","0.11356"
"346.60800","2.88850","688.65759","37.55768","0.11372"
"347.07200","2.89237","686.33185","37.43084","0.11387"
"347.53600","2.89600","682.98529","37.24833","0.11402"
"348.00000","2.90012","682.61725","37.22825","0.11418"
"348.46400","2.90400","680.64063","37.12045","0.11433"
"348.92800","2.90750","675.80615","36.85679","0.11447"
"349.39200","2.91169","675.34247","36.83150","0.11463"
"349.85600","2.91556","674.50983","36.78609","0.11479"
"350.32000","2.91912","668.99420","36.48529","0.11493"
"350.78400","2.92331","668.81799","36.47567","0.11509"
"351.24800","2.92712","668.26123","36.44531","0.11524"
"351.71200","2.93081","662.55212","36.13395","0.11539"
"352.17600","2.93481","661.47858","36.07540","0.11554"
"352.64000","2.93875","661.49316","36.07620","0.11570"
"353.10400","2.94244","655.91962","35.77223","0.11584"
"353.56800","2.94644","654.23816","35.68053","0.11600"
"354.03200","2.95025","653.69928","35.65114","0.11615"
"354.49600","2.95419","650.28705","35.46504","0.11631"
"354.96000","2.95800","647.60504","35.31877","0.11646"
"355.42400","2.96175","645.64978","35.21214","0.11660"
"355.88800","2.96581","643.84277","35.11359","0.11676"
"356.35200","2.96962","641.33893","34.97704","0.11691"
"356.81600","2.97325","638.04041","34.79714","0.11706"
"357.28000","2.97750","637.30249","34.75690","0.11722"
"357.74400","2.98131","635.03381","34.63317","0.11737"
"358.20800","2.98487","630.82147","34.40344","0.11751"
"358.67200","2.98919","631.00275","34.41333","0.11768"
"359.13600","2.99300","629.41309","34.32663","0.11783"
"359.60000","2.99650","623.21674","33.98870","0.11797"
"360.06400","3.00069","623.38745","33.99800","0.11814"
"360.52800","3.00469","622.82782","33.96748","0.11829"
"360.99200","3.00819","616.86499","33.64229","0.11843"
"361.45600","3.01225","615.52765","33.56935","0.11859"
"361.92000","3.01619","615.14166","33.54830","0.11875"
"362.38400","3.01981","609.53485","33.24252","0.11889"
"362.84800","3.02381","608.00055","33.15884","0.11905"
"363.31200","3.02775","606.74323","33.09027","0.11920"
"363.77600","3.03150","602.73071","32.87144","0.11935"
"364.24000","3.03537","600.33301","32.74067","0.11950"
"364.70400","3.03912","597.32452","32.57660","0.11965"
"365.16800","3.04319","596.24976","32.51798","0.11981"
"365.63200","3.04700","593.29889","32.35705","0.11996"
"366.09600","3.05062","588.72736","32.10773","0.12010"
"366.56000","3.05481","588.31549","32.08527","0.12027"
"367.02400","3.05862","585.47656","31.93044","0.12042"
"367.48800","3.06219","580.34296","31.65047","0.12056"
"367.95200","3.06637","579.71478","31.61621","0.12072"
"368.41600","3.07025","578.40460","31.54475","0.12088"
"368.88000","3.07381","572.36914","31.21559","0.12102"
"369.34400","3.07794","571.02917","31.14252","0.12118"
"369.80800","3.08181","570.11041","31.09241","0.12133"
"370.27200","3.08544","564.34509","30.77798","0.12147"
"370.73600","3.08944","562.44330","30.67426","0.12163"
"371.20000","3.09337","561.98376","30.64920","0.12179"
"371.66400","3.09712","556.97180","30.37586","0.12193"
"372.12800","3.10106","553.82983","30.20451","0.12209"
"372.59200","3.10487","552.70239","30.14302","0.12224"
"373.05600","3.10881","549.13885","29.94867","0.12239"
"373.52000","3.11269","545.55121","29.75301","0.12255"
"373.98400","3.11637","543.47955","29.64003","0.12269"
"374.44800","3.12050","541.55426","29.53503","0.12285"
"374.91200","3.12431","537.80780","29.33070","0.12300"
"375.37600","3.12794","534.10773","29.12891","0.12315"
"375.84000","3.13219","533.57819","29.10003","0.12331"
"376.30400","3.13600","530.50732","28.93255","0.12346"
"376.76800","3.13950","524.79102","28.62080","0.12360"
"377.23200","3.14375","524.34454","28.59645","0.12377"
"377.69600","3.14769","522.27344","28.48350","0.12392"
"378.16000","3.15119","516.19751","28.15213","0.12406"
"378.62400","3.15537","514.95233","28.08422","0.12423"
"379.08800","3.15931","514.02509","28.03365","0.12438"
"379.55200","3.16287","507.49738","27.67765","0.12452"
"380.01600","3.16687","505.17447","27.55096","0.12468"
"380.48000","3.17081","503.90045","27.48148","0.12484"
"380.94400","3.17450","498.73538","27.19979","0.12498"
"381.40800","3.17844","496.03690","27.05262","0.12514"
"381.87200","3.18231","493.84274","26.93296","0.12529"
"382.33600","3.18619","490.51819","26.75165","0.12544"
"382.80000","3.19006","486.56244","26.53591","0.12559"
"383.26400","3.19369","482.95493","26.33916","0.12574"
"383.72800","3.19781","481.13391","26.23985","0.12590"
"384.19200","3.20169","477.79727","26.05788","0.12605"
"384.65600","3.20531","472.75967","25.78314","0.12619"
"385.12000","3.20944","471.40176","25.70908","0.12636"
"385.58400","3.21331","468.50122","25.55090","0.12651"
"386.04800","3.21687","462.62216","25.23027","0.12665"
"386.51200","3.22094","460.87991","25.13525","0.12681"
"386.97600","3.22487","458.89960","25.02725","0.12696"
"387.44000","3.22850","452.23636","24.66385","0.12711"
"387.90400","3.23250","449.75262","24.52839","0.12726"
"388.36800","3.23650","448.80496","24.47671","0.12742"
"388.83200","3.24012","442.56024","24.13614","0.12756"
"389.29600","3.24412","439.58170","23.97370","0.12772"
"389.76000","3.24800","437.93652","23.88397","0.12787"
"390.22400","3.25187","432.37363","23.58059","0.12803"
"390.68800","3.25575","428.82465","23.38703","0.12818"
"391.15200","3.25950","426.45084","23.25757","0.12833"
"391.61600","3.26350","422.31833","23.03219","0.12848"
"392.08000","3.26737","418.48621","22.82320","0.12864"
"392.54400","3.27106","415.03348","22.63490","0.12878"
"393.00800","3.27519","412.13333","22.47673","0.12894"
"393.47200","3.27906","407.55124","22.22683","0.12910"
"393.93600","3.28256","403.07166","21.98253","0.12923"
"394.40000","3.28687","401.59421","21.90195","0.12940"
"394.86400","3.29075","397.41010","21.67376","0.12956"
"395.32800","3.29419","391.45358","21.34891","0.12969"
"395.79200","3.29850","389.90857","21.26465","0.12986"
"396.25600","3.30237","387.06717","21.10968","0.13001"
"396.72000","3.30587","379.54672","20.69954","0.13015"
"397.18400","3.31000","377.30756","20.57742","0.13031"
"397.64800","3.31400","375.07059","20.45542","0.13047"
"398.11200","3.31750","367.23364","20.02801","0.13061"
"398.57600","3.32156","364.38083","19.87243","0.13077"
"399.04000","3.32550","361.82672","19.73313","0.13093"
"399.50400","3.32925","355.32840","19.37873","0.13107"
"399.96800","3.33319","351.49609","19.16973","0.13123"
"400.43200","3.33694","347.48114","18.95076","0.13138"
"400.89600","3.34094","343.02206","18.70757","0.13153"
"401.36000","3.34469","337.63559","18.41381","0.13168"
"401.82400","3.34837","332.16443","18.11543","0.13183"
"402.28800","3.35256","328.58902","17.92043","0.13199"
"402.75200","3.35637","322.44424","17.58531","0.13214"
"403.21600","3.35994","314.21799","17.13667","0.13228"
"403.68000","3.36406","307.82953","16.78826","0.13244"
"404.14400","3.36800","298.11591","16.25850","0.13260"
"404.60800","3.37150","280.29001","15.28632","0.13274"
"405.07200","3.37562","256.02597","13.96302","0.13290"
"405.29800","3.37731","239.76700","13.07630","0.13297"