File: 60 per.is_metal_RawData/Specimen_RawData_1.csv
Time,Extension,Load,Tensile stress,Tensile strain (Extension)
(s),(mm),(N),(MPa),(mm/mm)
"0.00000","0.00000","-0.21840","-0.03204","0.00000"
"0.22400","0.00125","6.75385","0.99088","0.00005"
"0.44800","0.00381","34.81981","5.10854","0.00015"
"0.67200","0.00544","50.93563","7.47295","0.00021"
"0.89600","0.00756","72.23209","10.59743","0.00030"
"1.12000","0.00950","91.33626","13.40027","0.00037"
"1.34400","0.01100","105.57942","15.48994","0.00043"
"1.56800","0.01325","128.07368","18.79015","0.00052"
"1.79200","0.01506","143.87807","21.10887","0.00059"
"2.01600","0.01662","159.90849","23.46075","0.00065"
"2.24000","0.01875","179.52116","26.33820","0.00074"
"2.46400","0.02062","196.78595","28.87118","0.00081"
"2.68800","0.02225","212.85205","31.22829","0.00088"
"2.91200","0.02450","232.20396","34.06748","0.00096"
"3.13600","0.02612","247.34198","36.28844","0.00103"
"3.36000","0.02800","264.70911","38.83643","0.00110"
"3.58400","0.02981","279.39548","40.99112","0.00117"
"3.80800","0.03181","297.24820","43.61036","0.00125"
"4.03200","0.03362","313.58020","46.00648","0.00132"
"4.25600","0.03537","326.61057","47.91822","0.00139"
"4.48000","0.03737","344.53165","50.54749","0.00147"
"4.70400","0.03931","359.71671","52.77534","0.00155"
"4.92800","0.04087","371.32715","54.47875","0.00161"
"5.15200","0.04300","388.61752","57.01548","0.00169"
"5.37600","0.04500","403.59561","59.21297","0.00177"
"5.60000","0.04650","413.95258","60.73248","0.00183"
"5.82400","0.04875","431.10620","63.24915","0.00192"
"6.04800","0.05044","442.36938","64.90161","0.00199"
"6.27200","0.05219","454.59698","66.69556","0.00205"
"6.49600","0.05425","468.36404","68.71539","0.00214"
"6.72000","0.05612","480.54211","70.50207","0.00221"
"6.94400","0.05781","491.47815","72.10654","0.00228"
"7.16800","0.05987","503.53116","73.87488","0.00236"
"7.39200","0.06162","514.25562","75.44830","0.00243"
"7.61600","0.06356","526.26605","77.21040","0.00250"
"7.84000","0.06519","534.43494","78.40888","0.00257"
"8.06400","0.06731","547.04144","80.25843","0.00265"
"8.28800","0.06925","557.55505","81.80092","0.00273"
"8.51200","0.07075","563.57013","82.68341","0.00279"
"8.73600","0.07294","576.10760","84.52283","0.00287"
"8.96000","0.07475","583.74432","85.64324","0.00294"
"9.18400","0.07637","590.83612","86.68370","0.00301"
"9.40800","0.07856","601.72626","88.28143","0.00309"
"9.63200","0.08044","609.33276","89.39742","0.00317"
"9.85600","0.08194","614.78668","90.19758","0.00323"
"10.08000","0.08425","624.80798","91.66784","0.00332"
"10.30400","0.08594","630.25616","92.46716","0.00338"
"10.52800","0.08769","636.87811","93.43869","0.00345"
"10.75200","0.08956","643.31189","94.38261","0.00353"
"10.97600","0.09150","649.86072","95.34341","0.00360"
"11.20000","0.09331","655.83099","96.21934","0.00367"
"11.42400","0.09519","661.25269","97.01477","0.00375"
"11.64800","0.09706","667.13318","97.87752","0.00382"
"11.87200","0.09900","673.01355","98.74025","0.00390"
"12.09600","0.10062","676.12189","99.19629","0.00396"
"12.32000","0.10275","683.66492","100.30295","0.00405"
"12.54400","0.10475","688.83728","101.06181","0.00412"
"12.76800","0.10619","690.11316","101.24899","0.00418"
"12.99200","0.10844","697.89954","102.39137","0.00427"
"13.21600","0.11019","699.90668","102.68584","0.00434"
"13.44000","0.11187","703.51471","103.21519","0.00440"
"13.66400","0.11400","709.13757","104.04014","0.00449"
"13.88800","0.11587","712.08386","104.47240","0.00456"
"14.11200","0.11750","714.13531","104.77338","0.00463"
"14.33600","0.11969","719.78131","105.60172","0.00471"
"14.56000","0.12137","721.61371","105.87056","0.00478"
"14.78400","0.12319","724.81598","106.34037","0.00485"
"15.00800","0.12500","727.70062","106.76359","0.00492"
"15.23200","0.12700","730.96545","107.24258","0.00500"
"15.45600","0.12887","733.78070","107.65562","0.00507"
"15.68000","0.13056","735.23267","107.86864","0.00514"
"15.90400","0.13262","739.46124","108.48903","0.00522"
"16.12800","0.13450","741.76416","108.82690","0.00530"
"16.35200","0.13606","742.66583","108.95919","0.00536"
"16.57600","0.13825","747.04327","109.60142","0.00544"
"16.80000","0.14025","749.83264","110.01066","0.00552"
"17.02400","0.14169","748.97168","109.88435","0.00558"
"17.24800","0.14400","754.58905","110.70849","0.00567"
"17.47200","0.14556","754.22040","110.65440","0.00573"
"17.69600","0.14737","756.29956","110.95944","0.00580"
"17.92000","0.14944","759.32336","111.40308","0.00588"
"18.14400","0.15131","760.33429","111.55139","0.00596"
"18.36800","0.15300","761.34314","111.69940","0.00602"
"18.59200","0.15494","763.94598","112.08128","0.00610"
"18.81600","0.15681","764.90314","112.22170","0.00617"
"19.04000","0.15875","767.27856","112.57021","0.00625"
"19.26400","0.16037","767.55225","112.61037","0.00631"
"19.48800","0.16250","770.51434","113.04494","0.00640"
"19.71200","0.16444","772.28833","113.30521","0.00647"
"19.93600","0.16594","771.35205","113.16785","0.00653"
"20.16000","0.16812","774.72400","113.66256","0.00662"
"20.38400","0.16994","775.18939","113.73083","0.00669"
"20.60800","0.17156","775.39233","113.76061","0.00675"
"20.83200","0.17369","778.87677","114.27183","0.00684"
"21.05600","0.17569","779.95569","114.43012","0.00692"
"21.28000","0.17719","778.51263","114.21841","0.00698"
"21.50400","0.17950","783.57526","114.96116","0.00707"
"21.72800","0.18106","781.92383","114.71887","0.00713"
"21.95200","0.18287","782.71729","114.83528","0.00720"
"22.17600","0.18481","784.68341","115.12374","0.00728"
"22.40000","0.18669","785.51953","115.24641","0.00735"
"22.62400","0.18856","786.12360","115.33504","0.00742"
"22.84800","0.19031","786.77454","115.43053","0.00749"
"23.07200","0.19231","787.82318","115.58439","0.00757"
"23.29600","0.19425","789.59827","115.84482","0.00765"
"23.52000","0.19581","788.71075","115.71461","0.00771"
"23.74400","0.19787","790.96771","116.04573","0.00779"
"23.96800","0.19987","792.43530","116.26105","0.00787"
"24.19200","0.20144","791.03076","116.05499","0.00793"
"24.41600","0.20369","794.48102","116.56118","0.00802"
"24.64000","0.20537","793.32635","116.39178","0.00809"
"24.86400","0.20706","793.20026","116.37328","0.00815"
"25.08800","0.20912","796.35699","116.83641","0.00823"
"25.31200","0.21112","796.43054","116.84721","0.00831"
"25.53600","0.21269","795.10065","116.65209","0.00837"
"25.76000","0.21487","798.37421","117.13237","0.00846"
"25.98400","0.21650","797.02643","116.93463","0.00852"
"26.20800","0.21844","798.23322","117.11168","0.00860"
"26.43200","0.22019","798.15314","117.09993","0.00867"
"26.65600","0.22219","799.46649","117.29262","0.00875"
"26.88000","0.22406","800.04645","117.37771","0.00882"
"27.10400","0.22569","799.26959","117.26373","0.00889"
"27.32800","0.22781","801.18347","117.54453","0.00897"
"27.55200","0.22975","802.18408","117.69133","0.00905"
"27.77600","0.23125","800.45044","117.43698","0.00910"
"28.00000","0.23344","803.30371","117.85559","0.00919"
"28.22400","0.23537","803.56158","117.89342","0.00927"
"28.44800","0.23687","801.73358","117.62523","0.00933"
"28.67200","0.23919","805.76727","118.21703","0.00942"
"28.89600","0.24081","803.58051","117.89620","0.00948"
"29.12000","0.24262","803.50171","117.88464","0.00955"
"29.34400","0.24456","805.37488","118.15946","0.00963"
"29.56800","0.24650","805.57074","118.18819","0.00970"
"29.79200","0.24819","804.69055","118.05906","0.00977"
"30.01600","0.25019","806.21869","118.28326","0.00985"
"30.24000","0.25200","805.86633","118.23156","0.00992"
"30.46400","0.25400","807.32458","118.44551","0.01000"
"30.68800","0.25556","805.64612","118.19926","0.01006"
"30.91200","0.25769","807.41821","118.45924","0.01015"
"31.13600","0.25962","808.19421","118.57310","0.01022"
"31.36000","0.26112","806.54742","118.33149","0.01028"
"31.58400","0.26331","809.47736","118.76135","0.01037"
"31.80800","0.26519","808.87543","118.67303","0.01044"
"32.03200","0.26675","807.03943","118.40367","0.01050"
"32.25600","0.26887","810.09735","118.85231","0.01059"
"32.48000","0.27081","809.25415","118.72860","0.01066"
"32.70400","0.27237","808.04138","118.55067","0.01072"
"32.92800","0.27469","811.46442","119.05288","0.01081"
"33.15200","0.27625","809.01941","118.69416","0.01088"
"33.37600","0.27812","809.83154","118.81332","0.01095"
"33.60000","0.28000","810.38501","118.89452","0.01102"
"33.82400","0.28194","810.63861","118.93172","0.01110"
"34.04800","0.28375","810.23657","118.87273","0.01117"
"34.27200","0.28550","810.08801","118.85094","0.01124"
"34.49600","0.28750","810.94409","118.97654","0.01132"
"34.72000","0.28950","812.11395","119.14817","0.01140"
"34.94400","0.29100","810.15564","118.86086","0.01146"
"35.16800","0.29312","812.31866","119.17821","0.01154"
"35.39200","0.29512","812.71210","119.23593","0.01162"
"35.61600","0.29662","810.34479","118.88861","0.01168"
"35.84000","0.29887","813.54230","119.35773","0.01177"
"36.06400","0.30062","811.97137","119.12726","0.01184"
"36.28800","0.30225","810.81232","118.95721","0.01190"
"36.51200","0.30437","813.69617","119.38031","0.01198"
"36.73600","0.30625","812.64435","119.22599","0.01206"
"36.96000","0.30787","811.51788","119.06072","0.01212"
"37.18400","0.31006","813.80084","119.39566","0.01221"
"37.40800","0.31175","812.26910","119.17094","0.01227"
"37.63200","0.31362","812.81781","119.25144","0.01235"
"37.85600","0.31537","812.45795","119.19864","0.01242"
"38.08000","0.31744","813.40039","119.33691","0.01250"
"38.30400","0.31931","813.55402","119.35945","0.01257"
"38.52800","0.32087","811.89807","119.11650","0.01263"
"38.75200","0.32300","813.51178","119.35326","0.01272"
"38.97600","0.32494","813.81134","119.39720","0.01279"
"39.20000","0.32650","812.02826","119.13560","0.01285"
"39.42400","0.32869","814.67859","119.52444","0.01294"
"39.64800","0.33056","814.25189","119.46184","0.01301"
"39.87200","0.33206","812.10968","119.14754","0.01307"
"40.09600","0.33437","815.25165","119.60851","0.01316"
"40.32000","0.33606","813.51648","119.35394","0.01323"
"40.54400","0.33781","812.76990","119.24441","0.01330"
"40.76800","0.33975","814.00146","119.42509","0.01338"
"40.99200","0.34162","813.60669","119.36718","0.01345"
"41.21600","0.34344","813.08301","119.29034","0.01352"
"41.44000","0.34537","813.96252","119.41939","0.01360"
"41.66400","0.34719","813.29712","119.32176","0.01367"
"41.88800","0.34912","814.20087","119.45435","0.01375"
"42.11200","0.35075","812.62036","119.22247","0.01381"
"42.33600","0.35287","814.46936","119.49374","0.01389"
"42.56000","0.35481","814.61377","119.51493","0.01397"
"42.78400","0.35631","812.24664","119.16764","0.01403"
"43.00800","0.35856","814.84729","119.54919","0.01412"
"43.23200","0.36031","813.43707","119.34229","0.01419"
"43.45600","0.36200","812.54791","119.21185","0.01425"
"43.68000","0.36412","814.76855","119.53764","0.01434"
"43.90400","0.36600","814.00403","119.42548","0.01441"
"44.12800","0.36762","812.35431","119.18344","0.01447"
"44.35200","0.36987","815.09631","119.58572","0.01456"
"44.57600","0.37150","813.04291","119.28446","0.01463"
"44.80000","0.37331","812.83411","119.25383","0.01470"
"45.02400","0.37512","813.19928","119.30740","0.01477"
"45.24800","0.37712","813.77283","119.39156","0.01485"
"45.47200","0.37900","813.22064","119.31054","0.01492"
"45.69600","0.38075","812.53241","119.20956","0.01499"
"45.92000","0.38269","812.95605","119.27172","0.01507"
"46.14400","0.38462","813.57605","119.36269","0.01514"
"46.36800","0.38625","812.13843","119.15176","0.01521"
"46.59200","0.38837","813.79779","119.39522","0.01529"
"46.81600","0.39037","813.96063","119.41911","0.01537"
"47.04000","0.39181","811.11926","119.00224","0.01543"
"47.26400","0.39406","814.36353","119.47822","0.01551"
"47.48800","0.39575","812.22656","119.16470","0.01558"
"47.71200","0.39750","811.68805","119.08569","0.01565"
"47.93600","0.39956","813.59119","119.36491","0.01573"
"48.16000","0.40144","812.53229","119.20955","0.01580"
"48.38400","0.40312","811.33850","119.03440","0.01587"
"48.60800","0.40519","813.07220","119.28876","0.01595"
"48.83200","0.40694","811.64392","119.07922","0.01602"
"49.05600","0.40881","811.90326","119.11726","0.01609"
"49.28000","0.41056","811.00854","118.98599","0.01616"
"49.50400","0.41262","812.17102","119.15655","0.01625"
"49.72800","0.41450","812.10034","119.14618","0.01632"
"49.95200","0.41612","810.16913","118.86284","0.01638"
"50.17600","0.41825","811.53345","119.06300","0.01647"
"50.40000","0.42006","811.21112","119.01572","0.01654"
"50.62400","0.42169","810.05463","118.84605","0.01660"
"50.84800","0.42381","811.88611","119.11475","0.01669"
"51.07200","0.42581","811.48816","119.05636","0.01676"
"51.29600","0.42725","808.76099","118.65625","0.01682"
"51.52000","0.42962","813.04291","119.28446","0.01691"
"51.74400","0.43125","809.79803","118.80840","0.01698"
"51.96800","0.43300","809.36926","118.74549","0.01705"
"52.19200","0.43500","810.39349","118.89576","0.01713"
"52.41600","0.43687","809.88373","118.82097","0.01720"
"52.64000","0.43862","809.02771","118.69538","0.01727"
"52.86400","0.44056","809.56732","118.77455","0.01734"
"53.08800","0.44244","808.74011","118.65318","0.01742"
"53.31200","0.44437","809.53369","118.76962","0.01750"
"53.53600","0.44594","807.59314","118.48491","0.01756"
"53.76000","0.44806","809.06116","118.70029","0.01764"
"53.98400","0.45000","809.11682","118.70845","0.01772"
"54.20800","0.45156","807.03674","118.40327","0.01778"
"54.43200","0.45375","809.08844","118.70429","0.01786"
"54.65600","0.45550","807.73962","118.50640","0.01793"
"54.88000","0.45719","806.38629","118.30785","0.01800"
"55.10400","0.45931","808.61597","118.63497","0.01808"
"55.32800","0.46125","807.71393","118.50263","0.01816"
"55.55200","0.46275","805.23883","118.13950","0.01822"
"55.77600","0.46500","808.32404","118.59214","0.01831"
"56.00000","0.46662","805.58008","118.18957","0.01837"
"56.22400","0.46856","806.13019","118.27027","0.01845"
"56.44800","0.47037","806.07922","118.26279","0.01852"
"56.67200","0.47231","805.83356","118.22675","0.01859"
"56.89600","0.47419","805.33398","118.15346","0.01867"
"57.12000","0.47587","804.44983","118.02374","0.01874"
"57.34400","0.47794","804.81506","118.07732","0.01882"
"57.56800","0.47987","805.32373","118.15195","0.01889"
"57.79200","0.48137","802.94672","117.80322","0.01895"
"58.01600","0.48356","805.02637","118.10833","0.01904"
"58.24000","0.48550","804.15869","117.98103","0.01911"
"58.46400","0.48700","801.57031","117.60128","0.01917"
"58.68800","0.48931","804.95428","118.09776","0.01926"
"58.91200","0.49100","802.46942","117.73319","0.01933"
"59.13600","0.49269","801.31458","117.56376","0.01940"
"59.36000","0.49475","802.97552","117.80744","0.01948"
"59.58400","0.49669","801.87366","117.64578","0.01955"
"59.80800","0.49831","800.05505","117.37897","0.01962"
"60.03200","0.50044","801.73553","117.62552","0.01970"
"60.25600","0.50206","799.89246","117.35512","0.01977"
"60.48000","0.50406","800.74213","117.47977","0.01984"
"60.70400","0.50575","799.13129","117.24344","0.01991"
"60.92800","0.50781","799.83624","117.34687","0.01999"
"61.15200","0.50969","799.45160","117.29044","0.02007"
"61.37600","0.51131","797.56287","117.01333","0.02013"
"61.60000","0.51344","798.76215","117.18929","0.02021"
"61.82400","0.51537","798.50751","117.15192","0.02029"
"62.04800","0.51687","795.98157","116.78133","0.02035"
"62.27200","0.51906","798.26990","117.11707","0.02044"
"62.49600","0.52094","796.81036","116.90293","0.02051"
"62.72000","0.52250","794.77838","116.60481","0.02057"
"62.94400","0.52481","797.80988","117.04957","0.02066"
"63.16800","0.52637","794.65991","116.58743","0.02072"
"63.39200","0.52819","794.58997","116.57716","0.02079"
"63.61600","0.53019","794.95209","116.63029","0.02087"
"63.84000","0.53206","793.95258","116.48365","0.02095"
"64.06400","0.53387","792.83203","116.31925","0.02102"
"64.28800","0.53569","793.27301","116.38395","0.02109"
"64.51200","0.53762","792.31055","116.24274","0.02117"
"64.73600","0.53962","793.29077","116.38656","0.02125"
"64.96000","0.54119","790.62854","115.99597","0.02131"
"65.18400","0.54325","792.07941","116.20883","0.02139"
"65.40800","0.54525","792.13727","116.21732","0.02147"
"65.63200","0.54675","789.22760","115.79044","0.02153"
"65.85600","0.54900","791.39380","116.10825","0.02161"
"66.08000","0.55081","789.65723","115.85347","0.02169"
"66.30400","0.55237","787.73486","115.57143","0.02175"
"66.52800","0.55456","789.78546","115.87228","0.02183"
"66.75200","0.55637","788.25055","115.64709","0.02190"
"66.97600","0.55800","786.26776","115.35619","0.02197"
"67.20000","0.56025","788.72516","115.71672","0.02206"
"67.42400","0.56187","786.07874","115.32845","0.02212"
"67.64800","0.56375","785.98511","115.31472","0.02219"
"67.87200","0.56556","785.38965","115.22736","0.02227"
"68.09600","0.56756","785.08380","115.18248","0.02234"
"68.32000","0.56937","784.52814","115.10096","0.02242"
"68.54400","0.57106","783.04901","114.88395","0.02248"
"68.76800","0.57312","783.58154","114.96208","0.02256"
"68.99200","0.57506","784.02850","115.02766","0.02264"
"69.21600","0.57662","781.25714","114.62106","0.02270"
"69.44000","0.57881","783.23187","114.91078","0.02279"
"69.66400","0.58075","782.40930","114.79010","0.02286"
"69.88800","0.58219","779.50085","114.36339","0.02292"
"70.11200","0.58450","782.65564","114.82624","0.02301"
"70.33600","0.58619","780.07922","114.44824","0.02308"
"70.56000","0.58787","778.31781","114.18982","0.02314"
"70.78400","0.58994","780.15967","114.46004","0.02323"
"71.00800","0.59175","778.39313","114.20087","0.02330"
"71.23200","0.59356","777.08087","114.00835","0.02337"
"71.45600","0.59556","778.08606","114.15582","0.02345"
"71.68000","0.59731","776.33582","113.89903","0.02352"
"71.90400","0.59925","776.66846","113.94784","0.02359"
"72.12800","0.60094","774.98627","113.70103","0.02366"
"72.35200","0.60300","775.57916","113.78802","0.02374"
"72.57600","0.60494","775.34186","113.75320","0.02382"
"72.80000","0.60644","772.82361","113.38374","0.02388"
"73.02400","0.60869","774.35400","113.60828","0.02396"
"73.24800","0.61050","772.67645","113.36215","0.02404"
"73.47200","0.61206","771.01544","113.11846","0.02410"
"73.69600","0.61425","773.39740","113.46793","0.02418"
"73.92000","0.61619","771.74988","113.22621","0.02426"
"74.14400","0.61775","769.42358","112.88492","0.02432"
"74.36800","0.62000","772.41046","113.32313","0.02441"
"74.59200","0.62162","769.30786","112.86794","0.02447"
"74.81600","0.62344","768.62909","112.76836","0.02454"
"75.04000","0.62531","769.12213","112.84069","0.02462"
"75.26400","0.62731","768.30109","112.72023","0.02470"
"75.48800","0.62906","766.93054","112.51915","0.02477"
"75.71200","0.63094","766.61133","112.47232","0.02484"
"75.93600","0.63281","765.91034","112.36948","0.02491"
"76.16000","0.63475","766.28674","112.42470","0.02499"
"76.38400","0.63637","764.45074","112.15533","0.02505"
"76.60800","0.63850","765.90253","112.36833","0.02514"
"76.83200","0.64050","765.20227","112.26559","0.02522"
"77.05600","0.64187","761.96106","111.79006","0.02527"
"77.28000","0.64419","764.78546","112.20444","0.02536"
"77.50400","0.64587","762.25122","111.83263","0.02543"
"77.72800","0.64756","761.04932","111.65630","0.02549"
"77.95200","0.64975","762.90826","111.92903","0.02558"
"78.17600","0.65162","761.10986","111.66518","0.02565"
"78.40000","0.65319","759.32501","111.40332","0.02572"
"78.62400","0.65537","761.42529","111.71146","0.02580"
"78.84800","0.65706","758.72021","111.31458","0.02587"
"79.07200","0.65894","758.35718","111.26132","0.02594"
"79.29600","0.66075","757.94672","111.20110","0.02601"
"79.52000","0.66275","757.70544","111.16570","0.02609"
"79.74400","0.66462","756.88568","111.04543","0.02617"
"79.96800","0.66631","755.58386","110.85444","0.02623"
"80.19200","0.66837","755.92737","110.90484","0.02631"
"80.41600","0.67025","755.52917","110.84642","0.02639"
"80.64000","0.67181","753.65289","110.57114","0.02645"
"80.86400","0.67400","755.42133","110.83060","0.02654"
"81.08800","0.67594","754.58411","110.70776","0.02661"
"81.31200","0.67737","751.49036","110.25387","0.02667"
"81.53600","0.67975","755.36749","110.82269","0.02676"
"81.76000","0.68137","751.38739","110.23876","0.02683"
"81.98400","0.68312","750.69861","110.13771","0.02689"
"82.20800","0.68512","752.08038","110.34043","0.02697"
"82.43200","0.68706","750.26160","110.07359","0.02705"
"82.65600","0.68875","749.05334","109.89632","0.02712"
"82.88000","0.69081","750.12360","110.05334","0.02720"
"83.10400","0.69250","747.90002","109.72712","0.02726"
"83.32800","0.69450","748.71869","109.84723","0.02734"
"83.55200","0.69612","746.96985","109.59064","0.02741"
"83.77600","0.69812","747.20361","109.62495","0.02749"
"84.00000","0.70012","746.92883","109.58463","0.02756"
"84.22400","0.70169","744.70825","109.25884","0.02763"
"84.44800","0.70387","746.23370","109.48264","0.02771"
"84.67200","0.70569","744.75018","109.26499","0.02778"
"84.89600","0.70725","742.97290","109.00424","0.02784"
"85.12000","0.70944","745.10992","109.31777","0.02793"
"85.34400","0.71137","743.71198","109.11267","0.02801"
"85.56800","0.71287","740.87164","108.69596","0.02807"
"85.79200","0.71519","744.25793","109.19277","0.02816"
"86.01600","0.71675","740.73505","108.67592","0.02822"
"86.24000","0.71862","740.65344","108.66395","0.02829"
"86.46400","0.72056","740.73083","108.67530","0.02837"
"86.68800","0.72250","739.70721","108.52512","0.02844"
"86.91200","0.72425","738.74036","108.38327","0.02851"
"87.13600","0.72606","738.58905","108.36107","0.02859"
"87.36000","0.72800","737.80682","108.24631","0.02866"
"87.58400","0.73000","738.59265","108.36160","0.02874"
"87.80800","0.73156","735.76605","107.94690","0.02880"
"88.03200","0.73369","737.33453","108.17702","0.02889"
"88.25600","0.73562","736.42877","108.04413","0.02896"
"88.48000","0.73712","733.74530","107.65043","0.02902"
"88.70400","0.73937","736.51324","108.05652","0.02911"
"88.92800","0.74119","734.28601","107.72975","0.02918"
"89.15200","0.74281","732.55377","107.47561","0.02924"
"89.37600","0.74487","734.30457","107.73248","0.02933"
"89.60000","0.74681","733.02362","107.54455","0.02940"
"89.82400","0.74844","730.93805","107.23856","0.02947"
"90.04800","0.75062","732.81635","107.51414","0.02955"
"90.27200","0.75225","730.14703","107.12251","0.02962"
"90.49600","0.75419","730.44849","107.16674","0.02969"
"90.72000","0.75594","729.61084","107.04385","0.02976"
"90.94400","0.75794","729.44159","107.01901","0.02984"
"91.16800","0.75981","728.77216","106.92080","0.02991"
"91.39200","0.76144","727.35358","106.71267","0.02998"
"91.61600","0.76350","727.49963","106.73410","0.03006"
"91.84000","0.76550","727.94403","106.79930","0.03014"
"92.06400","0.76700","725.02179","106.37057","0.03020"
"92.28800","0.76919","727.16547","106.68507","0.03028"
"92.51200","0.77112","725.85638","106.49301","0.03036"
"92.73600","0.77262","723.17340","106.09938","0.03042"
"92.96000","0.77487","726.16803","106.53873","0.03051"
"93.18400","0.77650","723.31958","106.12083","0.03057"
"93.40800","0.77831","722.27063","105.96693","0.03064"
"93.63200","0.78031","723.25177","106.11089","0.03072"
"93.85600","0.78225","722.02533","105.93095","0.03080"
"94.08000","0.78394","720.27692","105.67443","0.03086"
"94.30400","0.78587","721.07068","105.79089","0.03094"
"94.52800","0.78775","719.67902","105.58671","0.03101"
"94.75200","0.78969","720.54626","105.71395","0.03109"
"94.97600","0.79131","718.39636","105.39853","0.03115"
"95.20000","0.79344","718.93335","105.47731","0.03124"
"95.42400","0.79537","718.48126","105.41098","0.03131"
"95.64800","0.79687","716.18872","105.07464","0.03137"
"95.87200","0.79912","718.05078","105.34782","0.03146"
"96.09600","0.80094","716.66315","105.14424","0.03153"
"96.32000","0.80250","714.22852","104.78705","0.03159"
"96.54400","0.80469","716.67920","105.14660","0.03168"
"96.76800","0.80656","714.58966","104.84003","0.03175"
"96.99200","0.80812","712.61737","104.55067","0.03182"
"97.21600","0.81037","715.41351","104.96090","0.03190"
"97.44000","0.81200","712.38635","104.51678","0.03197"
"97.66400","0.81381","711.88025","104.44253","0.03204"
"97.88800","0.81569","712.01532","104.46234","0.03211"
"98.11200","0.81769","711.33923","104.36315","0.03219"
"98.33600","0.81950","710.34875","104.21783","0.03226"
"98.56000","0.82125","709.64685","104.11485","0.03233"
"98.78400","0.82325","709.16632","104.04436","0.03241"
"99.00800","0.82519","709.42389","104.08215","0.03249"
"99.23200","0.82675","707.35107","103.77803","0.03255"
"99.45600","0.82887","708.42328","103.93534","0.03263"
"99.68000","0.83081","707.85315","103.85169","0.03271"
"99.90400","0.83231","705.33972","103.48294","0.03277"
"100.12800","0.83462","708.14465","103.89446","0.03286"
"100.35200","0.83637","705.56970","103.51669","0.03293"
"100.57600","0.83800","703.90259","103.27209","0.03299"
"100.80000","0.84006","705.61438","103.52324","0.03307"
"101.02400","0.84194","703.91034","103.27323","0.03315"
"101.24800","0.84369","702.28650","103.03499","0.03322"
"101.47200","0.84581","703.92371","103.27519","0.03330"
"101.69600","0.84750","701.29858","102.89005","0.03337"
"101.92000","0.84937","701.60065","102.93436","0.03344"
"102.14400","0.85106","700.41870","102.76096","0.03351"
"102.36800","0.85312","700.69647","102.80171","0.03359"
"102.59200","0.85506","700.04797","102.70657","0.03366"
"102.81600","0.85662","698.16510","102.43033","0.03373"
"103.04000","0.85875","699.12292","102.57085","0.03381"
"103.26400","0.86062","698.08136","102.41804","0.03388"
"103.48800","0.86225","696.45917","102.18005","0.03395"
"103.71200","0.86437","698.28033","102.44724","0.03403"
"103.93600","0.86637","697.00323","102.25986","0.03411"
"104.16000","0.86781","694.02728","101.82325","0.03417"
"104.38400","0.87012","697.22357","102.29219","0.03426"
"104.60800","0.87181","694.16827","101.84394","0.03432"
"104.83200","0.87350","693.22064","101.70491","0.03439"
"105.05600","0.87550","694.00323","101.81973","0.03447"
"105.28000","0.87744","692.90393","101.65844","0.03454"
"105.50400","0.87919","691.29193","101.42194","0.03461"
"105.72800","0.88112","692.07343","101.53659","0.03469"
"105.95200","0.88294","690.36633","101.28614","0.03476"
"106.17600","0.88487","690.75507","101.34317","0.03484"
"106.40000","0.88650","689.00116","101.08585","0.03490"
"106.62400","0.88862","689.87885","101.21462","0.03499"
"106.84800","0.89056","689.14325","101.10670","0.03506"
"107.07200","0.89206","686.43329","100.70911","0.03512"
"107.29600","0.89431","688.27362","100.97911","0.03521"
"107.52000","0.89606","686.90216","100.77790","0.03528"
"107.74400","0.89775","685.14130","100.51955","0.03534"
"107.96800","0.89987","686.85669","100.77122","0.03543"
"108.19200","0.90175","685.49915","100.57206","0.03550"
"108.41600","0.90331","682.99298","100.20437","0.03556"
"108.64000","0.90556","686.08807","100.65846","0.03565"
"108.86400","0.90719","682.73370","100.16633","0.03572"
"109.08800","0.90900","682.26855","100.09808","0.03579"
"109.31200","0.91087","682.23810","100.09362","0.03586"
"109.53600","0.91287","681.76569","100.02431","0.03594"
"109.76000","0.91475","680.68372","99.86557","0.03601"
"109.98400","0.91650","679.96027","99.75943","0.03608"
"110.20800","0.91844","679.28943","99.66101","0.03616"
"110.43200","0.92037","679.66113","99.71555","0.03624"
"110.65600","0.92194","677.72345","99.43126","0.03630"
"110.88000","0.92412","678.99158","99.61731","0.03638"
"111.10400","0.92606","678.37207","99.52642","0.03646"
"111.32800","0.92750","675.03284","99.03651","0.03652"
"111.55200","0.92987","678.28687","99.51392","0.03661"
"111.77600","0.93156","675.22601","99.06485","0.03668"
"112.00000","0.93325","673.96063","98.87920","0.03674"
"112.22400","0.93525","675.12903","99.05062","0.03682"
"112.44800","0.93719","673.85834","98.86419","0.03690"
"112.67200","0.93887","672.04663","98.59839","0.03696"
"112.89600","0.94100","674.07147","98.89546","0.03705"
"113.12000","0.94262","671.06342","98.45414","0.03711"
"113.34400","0.94456","671.43091","98.50806","0.03719"
"113.56800","0.94631","670.41553","98.35909","0.03726"
"113.79200","0.94831","670.31451","98.34427","0.03734"
"114.01600","0.95025","669.69977","98.25407","0.03741"
"114.24000","0.95187","667.96222","97.99915","0.03748"
"114.46400","0.95400","668.25061","98.04147","0.03756"
"114.68800","0.95587","668.04425","98.01118","0.03763"
"114.91200","0.95737","665.56879","97.64800","0.03769"
"115.13600","0.95956","667.55212","97.93899","0.03778"
"115.36000","0.96156","666.47656","97.78119","0.03786"
"115.58400","0.96300","663.48676","97.34254","0.03791"
"115.80800","0.96531","666.92999","97.84771","0.03800"
"116.03200","0.96694","663.17383","97.29663","0.03807"
"116.25600","0.96875","662.61163","97.21415","0.03814"
"116.48000","0.97075","663.39221","97.32867","0.03822"
"116.70400","0.97262","661.87939","97.10672","0.03829"
"116.92800","0.97437","660.72217","96.93694","0.03836"
"117.15200","0.97631","661.19336","97.00607","0.03844"
"117.37600","0.97812","659.56812","96.76762","0.03851"
"117.60000","0.98012","660.12000","96.84859","0.03859"
"117.82400","0.98169","657.88367","96.52049","0.03865"
"118.04800","0.98381","659.03656","96.68964","0.03873"
"118.27200","0.98575","658.08411","96.54990","0.03881"
"118.49600","0.98731","655.61884","96.18821","0.03887"
"118.72000","0.98950","657.17175","96.41605","0.03896"
"118.94400","0.99131","656.26617","96.28318","0.03903"
"119.16800","0.99294","653.82953","95.92570","0.03909"
"119.39200","0.99500","655.59741","96.18507","0.03917"
"119.61600","0.99694","654.18042","95.97717","0.03925"
"119.84000","0.99850","651.94440","95.64912","0.03931"
"120.06400","1.00081","654.37952","96.00639","0.03940"
"120.28800","1.00237","650.86786","95.49118","0.03946"
"120.51200","1.00425","651.12659","95.52914","0.03954"
"120.73600","1.00612","650.62994","95.45627","0.03961"
"120.96000","1.00806","650.04413","95.37032","0.03969"
"121.18400","1.00987","648.96240","95.21162","0.03976"
"121.40800","1.01162","648.34009","95.12032","0.03983"
"121.63200","1.01362","647.38348","94.97997","0.03991"
"121.85600","1.01562","648.08832","95.08338","0.03999"
"122.08000","1.01712","645.49854","94.70342","0.04004"
"122.30400","1.01931","646.90497","94.90977","0.04013"
"122.52800","1.02125","646.24524","94.81297","0.04021"
"122.75200","1.02275","643.27112","94.37663","0.04027"
"122.97600","1.02500","645.52350","94.70708","0.04035"
"123.20000","1.02669","643.23102","94.37075","0.04042"
"123.42400","1.02844","641.52899","94.12104","0.04049"
"123.64800","1.03050","643.17200","94.36209","0.04057"
"123.87200","1.03237","641.20416","94.07338","0.04064"
"124.09600","1.03406","639.83740","93.87286","0.04071"
"124.32000","1.03612","640.97809","94.04021","0.04079"
"124.54400","1.03787","638.64777","93.69833","0.04086"
"124.76800","1.03981","639.38580","93.80660","0.04094"
"124.99200","1.04150","637.70758","93.56039","0.04100"
"125.21600","1.04350","637.43048","93.51973","0.04108"
"125.44000","1.04550","637.17706","93.48255","0.04116"
"125.66400","1.04706","635.15692","93.18616","0.04122"
"125.88800","1.04919","636.06262","93.31905","0.04131"
"126.11200","1.05106","635.01813","93.16580","0.04138"
"126.33600","1.05256","632.54602","92.80312","0.04144"
"126.56000","1.05481","634.57550","93.10087","0.04153"
"126.78400","1.05669","632.99799","92.86942","0.04160"
"127.00800","1.05825","630.51160","92.50464","0.04166"
"127.23200","1.06056","633.18640","92.89706","0.04175"
"127.45600","1.06219","629.95099","92.42239","0.04182"
"127.68000","1.06394","629.13922","92.30329","0.04189"
"127.90400","1.06587","630.12933","92.44855","0.04196"
"128.12800","1.06781","628.41632","92.19723","0.04204"
"128.35200","1.06956","626.84790","91.96712","0.04211"
"128.57600","1.07144","627.13477","92.00921","0.04218"
"128.80000","1.07331","626.02020","91.84569","0.04226"
"129.02400","1.07531","626.07465","91.85368","0.04234"
"129.24800","1.07687","624.29028","91.59188","0.04240"
"129.47200","1.07900","624.52460","91.62626","0.04248"
"129.69600","1.08100","624.04431","91.55579","0.04256"
"129.92000","1.08244","621.55090","91.18998","0.04262"
"130.14400","1.08469","623.49768","91.47560","0.04270"
"130.36800","1.08650","621.71899","91.21464","0.04278"
"130.59200","1.08812","619.52344","90.89252","0.04284"
"130.81600","1.09025","621.32477","91.15680","0.04292"
"131.04000","1.09212","619.27136","90.85554","0.04300"
"131.26400","1.09375","617.33331","90.57121","0.04306"
"131.48800","1.09600","619.79413","90.93224","0.04315"
"131.71200","1.09756","616.56812","90.45894","0.04321"
"131.93600","1.09950","616.64661","90.47045","0.04329"
"132.16000","1.10125","615.61829","90.31959","0.04336"
"132.38400","1.10325","615.10284","90.24397","0.04344"
"132.60800","1.10512","614.06006","90.09097","0.04351"
"132.83200","1.10681","613.03589","89.94071","0.04358"
"133.05600","1.10887","612.90137","89.92097","0.04366"
"133.28000","1.11081","612.32990","89.83714","0.04373"
"133.50400","1.11237","610.32257","89.54263","0.04379"
"133.72800","1.11450","611.37585","89.69716","0.04388"
"133.95200","1.11650","610.77032","89.60832","0.04396"
"134.17600","1.11794","607.42365","89.11732","0.04401"
"134.40000","1.12025","610.17261","89.52063","0.04410"
"134.62400","1.12200","607.69696","89.15742","0.04417"
"134.84800","1.12362","605.94037","88.89970","0.04424"
"135.07200","1.12562","607.24890","89.09168","0.04432"
"135.29600","1.12756","605.71570","88.86674","0.04439"
"135.52000","1.12925","603.49011","88.54021","0.04446"
"135.74400","1.13137","604.99908","88.76160","0.04454"
"135.96800","1.13306","602.76141","88.43330","0.04461"
"136.19200","1.13500","602.42401","88.38380","0.04469"
"136.41600","1.13662","601.38928","88.23199","0.04475"
"136.64000","1.13875","601.55176","88.25584","0.04483"
"136.86400","1.14069","600.51044","88.10306","0.04491"
"137.08800","1.14219","598.27826","87.77557","0.04497"
"137.31200","1.14437","599.04938","87.88870","0.04505"
"137.53600","1.14619","598.17627","87.76060","0.04513"
"137.76000","1.14781","596.13263","87.46077","0.04519"
"137.98400","1.15000","597.12085","87.60576","0.04528"
"138.20800","1.15194","596.06244","87.45048","0.04535"
"138.43200","1.15344","593.34125","87.05124","0.04541"
"138.65600","1.15575","596.23730","87.47613","0.04550"
"138.88000","1.15737","592.65155","86.95005","0.04557"
"139.10400","1.15912","591.69055","86.80906","0.04563"
"139.32800","1.16106","592.29028","86.89705","0.04571"
"139.55200","1.16300","590.96381","86.70244","0.04579"
"139.77600","1.16481","589.35620","86.46658","0.04586"
"140.00000","1.16669","589.27612","86.45483","0.04593"
"140.22400","1.16856","587.90308","86.25339","0.04601"
"140.44800","1.17050","588.31543","86.31388","0.04608"
"140.67200","1.17206","586.18970","86.00201","0.04614"
"140.89600","1.17425","586.65106","86.06969","0.04623"
"141.12000","1.17619","585.82745","85.94886","0.04631"
"141.34400","1.17762","582.97284","85.53005","0.04636"
"141.56800","1.17994","585.12714","85.84612","0.04645"
"141.79200","1.18162","582.56415","85.47009","0.04652"
"142.01600","1.18331","580.81360","85.21326","0.04659"
"142.24000","1.18537","582.27521","85.42770","0.04667"
"142.46400","1.18737","580.83588","85.21653","0.04675"
"142.68800","1.18894","578.36847","84.85453","0.04681"
"142.91200","1.19119","580.84888","85.21844","0.04690"
"143.13600","1.19281","577.15210","84.67607","0.04696"
"143.36000","1.19469","576.63470","84.60016","0.04703"
"143.58400","1.19650","576.39490","84.56498","0.04711"
"143.80800","1.19844","575.58691","84.44643","0.04718"
"144.03200","1.20031","574.40985","84.27374","0.04726"
"144.25600","1.20206","573.20294","84.09668","0.04733"
"144.48000","1.20406","572.65057","84.01563","0.04740"
"144.70400","1.20600","572.52209","83.99679","0.04748"
"144.92800","1.20750","569.98596","83.62470","0.04754"
"145.15200","1.20969","571.36426","83.82692","0.04763"
"145.37600","1.21169","569.91418","83.61417","0.04770"
"145.60000","1.21312","567.18213","83.21334","0.04776"
"145.82400","1.21544","569.78143","83.59470","0.04785"
"146.04800","1.21706","566.35382","83.09182","0.04792"
"146.27200","1.21887","565.23700","82.92796","0.04799"
"146.49600","1.22087","566.45856","83.10719","0.04807"
"146.72000","1.22275","564.38458","82.80290","0.04814"
"146.94400","1.22450","562.68579","82.55367","0.04821"
"147.16800","1.22650","563.62225","82.69106","0.04829"
"147.39200","1.22825","560.79578","82.27637","0.04836"
"147.61600","1.23019","561.23395","82.34066","0.04843"
"147.84000","1.23181","559.50153","82.08649","0.04850"
"148.06400","1.23394","559.66254","82.11012","0.04858"
"148.28800","1.23587","558.49359","81.93861","0.04866"
"148.51200","1.23744","556.18945","81.60056","0.04872"
"148.73600","1.23956","556.84906","81.69734","0.04880"
"148.96000","1.24150","556.31165","81.61849","0.04888"
"149.18400","1.24306","553.49084","81.20464","0.04894"
"149.40800","1.24519","555.02307","81.42944","0.04902"
"149.63200","1.24712","553.34766","81.18363","0.04910"
"149.85600","1.24862","550.53363","80.77078","0.04916"
"150.08000","1.25094","553.13861","81.15296","0.04925"
"150.30400","1.25250","549.65588","80.64200","0.04931"
"150.52800","1.25437","548.91187","80.53284","0.04938"
"150.75200","1.25631","548.77997","80.51350","0.04946"
"150.97600","1.25819","546.98059","80.24950","0.04953"
"151.20000","1.26000","546.00806","80.10682","0.04961"
"151.42400","1.26181","545.40338","80.01810","0.04968"
"151.64800","1.26375","543.86475","79.79237","0.04975"
"151.87200","1.26575","544.56348","79.89487","0.04983"
"152.09600","1.26725","541.36774","79.42602","0.04989"
"152.32000","1.26944","542.53571","79.59737","0.04998"
"152.54400","1.27137","541.49982","79.44540","0.05005"
"152.76800","1.27287","538.85083","79.05676","0.05011"
"152.99200","1.27512","540.04614","79.23212","0.05020"
"153.21600","1.27681","537.87292","78.91328","0.05027"
"153.44000","1.27850","536.08875","78.65152","0.05033"
"153.66400","1.28069","537.55829","78.86712","0.05042"
"153.88800","1.28250","534.85541","78.47057","0.05049"
"154.11200","1.28412","532.80426","78.16964","0.05056"
"154.33600","1.28631","534.69244","78.44666","0.05064"
"154.56000","1.28800","531.47107","77.97404","0.05071"
"154.78400","1.28994","531.43585","77.96887","0.05078"
"155.00800","1.29169","530.16547","77.78249","0.05085"
"155.23200","1.29362","529.18036","77.63796","0.05093"
"155.45600","1.29556","528.31702","77.51130","0.05101"
"155.68000","1.29719","526.64185","77.26553","0.05107"
"155.90400","1.29931","526.43060","77.23454","0.05115"
"156.12800","1.30125","525.80762","77.14314","0.05123"
"156.35200","1.30275","522.92163","76.71973","0.05129"
"156.57600","1.30494","524.16901","76.90273","0.05138"
"156.80000","1.30681","522.22021","76.61681","0.05145"
"157.02400","1.30837","520.00885","76.29238","0.05151"
"157.24800","1.31062","521.71442","76.54261","0.05160"
"157.47200","1.31231","518.76904","76.11048","0.05167"
"157.69600","1.31400","517.26630","75.89001","0.05173"
"157.92000","1.31606","518.06476","76.00716","0.05181"
"158.14400","1.31794","515.97498","75.70055","0.05189"
"158.36800","1.31969","514.25745","75.44857","0.05196"
"158.59200","1.32169","514.86169","75.53722","0.05203"
"158.81600","1.32350","512.36707","75.17123","0.05211"
"159.04000","1.32544","512.19336","75.14574","0.05218"
"159.26400","1.32706","510.26187","74.86237","0.05225"
"159.48800","1.32912","509.88998","74.80780","0.05233"
"159.71200","1.33112","509.02319","74.68063","0.05241"
"159.93600","1.33262","506.52359","74.31390","0.05247"
"160.16000","1.33481","507.40298","74.44292","0.05255"
"160.38400","1.33669","505.87012","74.21803","0.05263"
"160.60800","1.33819","503.41147","73.85732","0.05268"
"160.83200","1.34037","504.88376","74.07332","0.05277"
"161.05600","1.34225","502.45193","73.71654","0.05284"
"161.28000","1.34387","500.04184","73.36295","0.05291"
"161.50400","1.34612","502.14417","73.67139","0.05300"
"161.72800","1.34775","498.25797","73.10123","0.05306"
"161.95200","1.34956","497.42804","72.97947","0.05313"
"162.17600","1.35144","497.12888","72.93558","0.05321"
"162.40000","1.35337","495.58051","72.70840","0.05328"
"162.62400","1.35525","494.21793","72.50850","0.05336"
"162.84800","1.35694","493.13177","72.34914","0.05342"
"163.07200","1.35900","491.95612","72.17666","0.05350"
"163.29600","1.36087","491.25754","72.07417","0.05358"
"163.52000","1.36250","488.94360","71.73468","0.05364"
"163.74400","1.36462","489.17700","71.76893","0.05373"
"163.96800","1.36662","488.71994","71.70187","0.05380"
"164.19200","1.36806","485.16559","71.18040","0.05386"
"164.41600","1.37031","486.67508","71.40186","0.05395"
"164.64000","1.37212","484.04742","71.01635","0.05402"
"164.86400","1.37375","481.84131","70.69268","0.05408"
"165.08800","1.37581","482.94821","70.85508","0.05417"
"165.31200","1.37775","480.59641","70.51003","0.05424"
"165.53600","1.37937","478.24304","70.16476","0.05431"
"165.76000","1.38156","479.98874","70.42088","0.05439"
"165.98400","1.38325","476.43631","69.89970","0.05446"
"166.20800","1.38506","475.58313","69.77452","0.05453"
"166.43200","1.38687","474.41913","69.60374","0.05460"
"166.65600","1.38887","473.38708","69.45233","0.05468"
"166.88000","1.39081","472.05429","69.25679","0.05476"
"167.10400","1.39237","470.06760","68.96532","0.05482"
"167.32800","1.39450","469.68771","68.90958","0.05490"
"167.55200","1.39637","468.62778","68.75407","0.05498"
"167.77600","1.39794","466.47684","68.43850","0.05504"
"168.00000","1.40012","466.71344","68.47321","0.05512"
"168.22400","1.40206","465.33054","68.27032","0.05520"
"168.44800","1.40356","461.98926","67.78011","0.05526"
"168.67200","1.40587","464.39920","68.13368","0.05535"
"168.89600","1.40750","460.52747","67.56565","0.05541"
"169.12000","1.40925","458.49680","67.26772","0.05548"
"169.34400","1.41125","459.31372","67.38757","0.05556"
"169.56800","1.41312","456.67770","67.00084","0.05563"
"169.79200","1.41487","454.58908","66.69440","0.05570"
"170.01600","1.41687","454.97906","66.75163","0.05578"
"170.24000","1.41869","452.13116","66.33380","0.05585"
"170.46400","1.42062","452.30286","66.35899","0.05593"
"170.68800","1.42225","449.72198","65.98034","0.05599"
"170.91200","1.42437","449.58997","65.96097","0.05608"
"171.13600","1.42631","448.15344","65.75021","0.05615"
"171.36000","1.42775","445.05811","65.29608","0.05621"
"171.58400","1.43006","445.59970","65.37554","0.05630"
"171.80800","1.43181","443.30460","65.03882","0.05637"
"172.03200","1.43344","441.05597","64.70892","0.05643"
"172.25600","1.43556","441.84183","64.82421","0.05652"
"172.48000","1.43750","439.67752","64.50668","0.05659"
"172.70400","1.43906","436.63831","64.06078","0.05666"
"172.92800","1.44137","438.91180","64.39434","0.05675"
"173.15200","1.44294","434.39044","63.73099","0.05681"
"173.37600","1.44475","433.28632","63.56900","0.05688"
"173.60000","1.44662","432.62085","63.47137","0.05695"
"173.82400","1.44856","430.74493","63.19615","0.05703"
"174.04800","1.45044","429.01981","62.94305","0.05710"
"174.27200","1.45219","427.83813","62.76968","0.05717"
"174.49600","1.45419","425.57715","62.43796","0.05725"
"174.72000","1.45612","425.64343","62.44769","0.05733"
"174.94400","1.45762","422.29468","61.95638","0.05739"
"175.16800","1.45981","422.74384","62.02228","0.05747"
"175.39200","1.46181","420.81866","61.73983","0.05755"
"175.61600","1.46325","417.86035","61.30580","0.05761"
"175.84000","1.46556","418.75327","61.43681","0.05770"
"176.06400","1.46725","415.80270","61.00392","0.05777"
"176.28800","1.46894","413.22223","60.62533","0.05783"
"176.51200","1.47100","414.02383","60.74294","0.05791"
"176.73600","1.47287","411.18994","60.32716","0.05799"
"176.96000","1.47456","408.50433","59.93315","0.05805"
"177.18400","1.47675","409.27817","60.04668","0.05814"
"177.40800","1.47837","405.53400","59.49736","0.05820"
"177.63200","1.48031","404.38083","59.32817","0.05828"
"177.85600","1.48200","402.71176","59.08330","0.05835"
"178.08000","1.48406","401.39734","58.89045","0.05843"
"178.30400","1.48600","399.55075","58.61953","0.05850"
"178.52800","1.48762","397.21671","58.27710","0.05857"
"178.75200","1.48969","395.81931","58.07208","0.05865"
"178.97600","1.49162","395.18661","57.97926","0.05873"
"179.20000","1.49312","391.61960","57.45593","0.05878"
"179.42400","1.49531","391.71671","57.47017","0.05887"
"179.64800","1.49725","389.58978","57.15813","0.05895"
"179.87200","1.49875","386.19260","56.65971","0.05901"
"180.09600","1.50106","387.31165","56.82389","0.05910"
"180.32000","1.50262","382.95755","56.18509","0.05916"
"180.54400","1.50450","381.13074","55.91707","0.05923"
"180.76800","1.50650","380.84296","55.87485","0.05931"
"180.99200","1.50831","377.67307","55.40978","0.05938"
"181.21600","1.51012","375.08472","55.03003","0.05945"
"181.44000","1.51206","374.94998","55.01027","0.05953"
"181.66400","1.51387","371.27036","54.47042","0.05960"
"181.88800","1.51587","370.68420","54.38442","0.05968"
"182.11200","1.51744","367.15924","53.86726","0.05974"
"182.33600","1.51956","366.01038","53.69870","0.05983"
"182.56000","1.52150","364.08060","53.41558","0.05990"
"182.78400","1.52300","360.25647","52.85453","0.05996"
"183.00800","1.52519","358.87442","52.65176","0.06005"
"183.23200","1.52700","355.69644","52.18551","0.06012"
"183.45600","1.52862","351.73703","51.60461","0.06018"
"183.68000","1.53081","350.26596","51.38879","0.06027"
"183.90400","1.53269","344.30154","50.51373","0.06034"
"184.12800","1.53425","337.63571","49.53576","0.06040"
"184.35200","1.53644","334.06686","49.01216","0.06049"
"184.57600","1.53812","324.34036","47.58515","0.06056"
"184.80000","1.54000","317.39188","46.56571","0.06063"
"185.02400","1.54187","311.61905","45.71876","0.06070"
"185.24800","1.54375","305.56454","44.83048","0.06078"
"185.47200","1.54562","301.20291","44.19057","0.06085"
"185.69600","1.54737","298.55444","43.80200","0.06092"
"185.92000","1.54937","294.45221","43.20015","0.06100"
"186.14400","1.55137","291.35107","42.74517","0.06108"
"186.36800","1.55287","286.91846","42.09484","0.06114"
"186.59200","1.55506","285.07825","41.82486","0.06122"
"186.81600","1.55700","281.74258","41.33547","0.06130"
"187.04000","1.55850","277.64758","40.73468","0.06136"
"187.26400","1.56075","276.31897","40.53976","0.06145"
"187.48800","1.56244","272.69485","40.00805","0.06151"
"187.71200","1.56412","268.96796","39.46126","0.06158"
"187.93600","1.56625","267.86966","39.30013","0.06166"
"188.16000","1.56806","263.74445","38.69490","0.06173"
"188.38400","1.56981","260.24109","38.18091","0.06180"
"188.60800","1.57187","259.66904","38.09698","0.06188"
"188.83200","1.57362","254.80968","37.38405","0.06195"
"189.05600","1.57550","252.25920","37.00986","0.06203"
"189.28000","1.57725","249.46773","36.60031","0.06210"
"189.50400","1.57925","245.54439","36.02470","0.06218"
"189.72800","1.58119","242.89247","35.63563","0.06225"
"189.95200","1.58275","239.42305","35.12662","0.06231"
"190.17600","1.58487","236.55771","34.70624","0.06240"
"190.40000","1.58681","233.87260","34.31229","0.06247"
"190.62400","1.58831","229.80646","33.71574","0.06253"
"190.84800","1.59050","228.30609","33.49561","0.06262"
"191.07200","1.59244","224.48834","32.93550","0.06269"
"191.29600","1.59400","220.42873","32.33990","0.06276"
"191.52000","1.59625","220.05910","32.28567","0.06284"
"191.74400","1.59787","215.26489","31.58229","0.06291"
"191.96800","1.59969","212.22704","31.13659","0.06298"
"192.19200","1.60162","210.39310","30.86753","0.06306"
"192.41600","1.60350","206.52290","30.29972","0.06313"
"192.64000","1.60531","202.90739","29.76928","0.06320"
"192.86400","1.60719","201.67087","29.58786","0.06328"
"193.08800","1.60912","196.90602","28.88879","0.06335"
"193.31200","1.61100","194.99136","28.60789","0.06343"
"193.53600","1.61262","191.92889","28.15858","0.06349"
"193.76000","1.61475","189.21970","27.76111","0.06357"
"193.98400","1.61675","186.15405","27.31133","0.06365"
"194.20800","1.61819","182.00587","26.70274","0.06371"
"194.43200","1.62044","179.30293","26.30618","0.06380"
"194.65600","1.62225","175.54204","25.75441","0.06387"
"194.88000","1.62381","170.94977","25.08066","0.06393"
"195.10400","1.62594","169.05386","24.80250","0.06401"
"195.32800","1.62787","163.73468","24.02211","0.06409"
"195.37600","1.62831","163.17828","23.94048","0.06411"